Workbook
Name Excel_BuiltIn__FilterDatabase_5: NA()

Sheet COST SHEET   (2)
A1: GLM PD Without jet AS PER MIS | B1: 244.57 | D1: OLD RATE
A3: Month | B3: 44593
A4: Ptr P/D chemical cost kg/kg
A5: Chemical Name | B5: Rate | C5: cons. | D5: cost
A6: RUCOLASE HCH | B6: 88.36 | C6: 950 | D6: =+B6*C6 -> 83942
A7: VEROLAN SEFE | B7: 67.95 | C7: 461 | D7: =+B7*C7 -> 31324.95
A8: GREEN ACID | B8: 35.2 | D8: =+B8*C8 -> 0
A9: ACETIC ACID | B9: 120.74 | C9: 160 | D9: =+B9*C9 -> 19318.4
A10: NEUTRACID NVM | B10: 216.74 | C10: 60 | D10: =+B10*C10 -> 13004.4
A11: RUCO ACID C | B11: 80.75 | D11: =+B11*C11 -> 0
A12: FINOCON IDU | B12: 92 | D12: =+B12*C12 -> 0
A13: FELOSAN HLDN | B13: 184.21 | C13: 3900 | D13: =+B13*C13 -> 718419
A14: LUFIBROL ANTOX.IN | B14: 215.52 | C14: =3700-2988 -> 712 | D14: =+B14*C14 -> 153450.24
A15: Hydrogen Peroxide | B15: 24.55 | C15: =39615-17583-2000 -> 20032 | D15: =+B15*C15 -> 491785.6
A16: HYDROGEN PEROXIDE (CAR BOY) | B16: 52.2 | D16: =+B16*C16 -> 0
A17: NAOH 100% | B17: 24.51 | C17: =13749+5000+1000 -> 19749 | D17: =+B17*C17 -> 484047.99
A18: OXALIC ACID | B18: 68.35 | C18: 50 | D18: =+B18*C18 -> 3417.5
A19: BRT | B19: 105.6 | C19: =12700-7332 -> 5368 | D19: =+B19*C19 -> 566860.8
C20: Total cost | D20: =SUM(D6:D19) -> 2565570.9
C21: Ptr prod. mtrs | D21: 1591548
C22: Ptr prod in kg | D22: =+D21*$B$1/1000 -> 389244.89
C23: cost kg/kg | D23: =+D20/D22 -> 6.5911484
A26: Perble chemical cost kg/kg
A27: CHEMICAL NAME | B27: RATE | C27: cons. | D27: cost
A28: Caustic Lye (NaOH) | B28: 24.51 | C28: =74380-13749-5000-1000 -> 54631 | D28: =+B28*C28 -> 1339005.8
A29: LUFIBROL ANTOX.IN | B29: 215.52 | C29: 2988 | D29: =+B29*C29 -> 643973.76
A30: VEROLAN SEFE | B30: 67.95 | C30: =1600-461 -> 1139 | D30: =+B30*C30 -> 77395.05
A31: Hydrogen Peroxide | B31: 24.55 | C31: =17583+2000 -> 19583 | D31: =+B31*C31 -> 480762.65
A32: HYDROGEN PEROXIDE (CAR BOY) | B32: 32 | D32: =+B32*C32 -> 0
A33: CONTABON BRT | B33: 105.6 | C33: 7332 | D33: =+B33*C33 -> 774259.2
A34: SIRRIX 2UDI | B34: 87.75 | D34: =+B34*C34 -> 0
A35: FELOSAN HLDN | B35: 163.75 | D35: =+B35*C35 -> 0
A36: HOSTAPAL MRZ | B36: 222.7 | C36: 3500 | D36: =+B36*C36 -> 779450
C37: Total cost | D37: =SUM(D28:D36) -> 4094846.5
C38: Perble prod. mtrs | D38: 2437894
C39: Perble prod in kg | D39: =+D38*$B$1/1000 -> 596235.74
C40: cost kg/kg | D40: =+(D37)/D39 -> 6.8678313
C42: Total perble +ptr cost | D42: =+D37+D20 -> 6660417.3
C43: Ptr +Perble prod. mtrs | D43: =+D38+D21 -> 4029442
C44: Ptr +Perble prod in kg | D44: =+D39+D22 -> 985480.63
...

Sheet FRONT PAGE
A1: PERFORMANCE REVIEW - PREPARATORY DEPARTMENT AUG-2024 | Q1: PERFORMANCE REVIEW - PREPARATORY DEPARTMENT AUG-2024 | AM1: PERFORMANCE REVIEW - PREPARATORY DEPARTMENT AUG-2024
A2: SR. | B2: PARAMETER | C2: OSTHOFF-1 | E2: OSTHOFF-2 | G2: PTR | I2: PERBLE | K2: MERCERISER-I | M2: MERCERISER-2 | O2: NPS | Q2: SR. | R2: PARAMETER | S2: XETMA 2 | U2: XETMA 3 | W2: LAFFER-1 | Y2: LAFFER-2 | AA2: LAFFER-3 | AC2: LAFFER-4 | AE2: Lafer-5-Raising | AG2: Lafer-5-Shearing | AI2: SWASTIK | AK2: SOAPER | AM2: SR. | AN2: PARAMETER | AO2: BATCHING ST-1 | AQ2: BATCHING ST-2
A3: NO. | Q3: NO. | AM3: NO.
A4: 1 | B4: PROCESSED , MTRS | C4: ='Osthoff-1'!$B$35 -> 0 | E4: ='Osthoff-2'!$B$35 -> 0 | G4: =PTR!$B$35 -> 0 | I4: =Perble!$B$35 -> 0 | K4: ='Merceriser-1'!$B$35 -> 0 | M4: ='Merceriser-2'!$B$35 -> 0 | O4: =NPS!$B$35 -> 0 | Q4: 1 | R4: PROCESSED , MTRS | S4: ='Xetma-2'!B35 -> 0 | U4: ='Xetma-3'!$B$35 -> 0 | W4: ='Lafer-1'!$B$35 -> 0 | Y4: ='Lafer-2'!$B$35 -> 0 | AA4: ='Lafer-3'!$B$35 -> 0 | AC4: ='Lafer-4'!$B$35 -> 0 | AE4: ='Lafer-5-Raising'!$B$35 -> 0 | AG4: ='Lafer-5-Shearing'!$B$35 -> 0 | AI4: ='Lafer-4'!$B$35 -> 0 | AK4: =Soaper!$B$35 -> 0 | AM4: 1 | AN4: PROCESSED , MTRS | AO4: =+#REF! -> #REF! | AQ4: =+#REF! -> #REF!
B5: EFFECTIVE. PROCESSED , MTRS | C5: ='Osthoff-1'!$E$35 -> 0 | E5: ='Osthoff-2'!$E$35 -> 0 | G5: =PTR!$E$35 -> 0 | I5: =Perble!$E$35 -> 0 | K5: ='Merceriser-1'!$E$35 -> 0 | M5: ='Merceriser-2'!$E$35 -> 0 | O5: =NPS!$E$35 -> 0 | R5: EFFECTIVE. PROCESSED , MTRS | S5: ='Xetma-2'!E35 -> 0 | U5: ='Xetma-3'!$E$35 -> 0 | W5: ='Lafer-1'!$E$35 -> 0 | Y5: ='Lafer-2'!$E$35 -> 0 | AA5: ='Lafer-3'!$E$35 -> 0 | AC5: ='Lafer-4'!$E$35 -> 0 | AE5: ='Lafer-5-Raising'!$E$35 -> 0 | AG5: ='Lafer-5-Shearing'!$E$35 -> 0 | AI5: ='Lafer-4'!$E$35 -> 0 | AK5: =Soaper!$E$35 -> 0 | AN5: EFFECTIVE. PROCESSED , MTRS | AO5: =+#REF! -> #REF! | AQ5: =+#REF! -> #REF!
A7: 2 | B7: TOTAL HRS. RUN | C7: ='Osthoff-1'!$I$35 -> 0 | E7: ='Osthoff-2'!$I$35 -> 0 | G7: =PTR!$I$35 -> 0 | I7: =Perble!$I$35 -> 0 | K7: ='Merceriser-1'!$I$35 -> 0 | M7: ='Merceriser-2'!$I$35 -> 0 | O7: =NPS!$I$35 -> 0 | Q7: 2 | R7: TOTAL HRS. RUN | S7: ='Xetma-2'!I35 -> 0 | U7: ='Xetma-3'!$I$35 -> 0 | W7: ='Lafer-1'!$I$35 -> 0 | Y7: ='Lafer-2'!$I$35 -> 0 | AA7: ='Lafer-3'!$I$35 -> 0 | AC7: ='Lafer-4'!$I$35 -> 0 | AE7: ='Lafer-5-Raising'!$I$35 -> 0 | AG7: ='Lafer-5-Shearing'!$I$35 -> 0 | AI7: ='Lafer-4'!$I$35 -> 0 | AK7: =Soaper!$I$35 -> 0 | AM7: 2 | AN7: TOTAL HRS. RUN | AO7: =+#REF! -> #REF! | AQ7: =+#REF! -> #REF!
A8: 3 | B8: UTILIZATION % | C8: =C7/C10*100 -> 0 | E8: =E7/E10*100 -> 0 | G8: =G7/G10*100 -> 0 | I8: =I7/I10*100 -> 0 | K8: =K7/K10*100 -> 0 | M8: =M7/M10*100 -> 0 | O8: =O7/O10*100 -> 0 | Q8: 3 | R8: UTILIZATION % | S8: =+S7/S10*100 -> 0 | U8: =+U7/U10*100 -> 0 | W8: =+W7/W10*100 -> 0 | Y8: =+Y7/Y10*100 -> 0 | AA8: =+AA7/AA10*100 -> 0 | AC8: =+AC7/AC10*100 -> 0 | AE8: =+AE7/AE10*100 -> 0 | AG8: =+AG7/AG10*100 -> 0 | AI8: =+AI7/AI10*100 -> 0 | AK8: =+AK7/AK10*100 -> 0 | AM8: 3 | AN8: UTILIZATION % | AO8: =+AO7/AO10*100 -> #REF! | AQ8: =+AQ7/AQ10*100 -> #REF!
B9: AVRAGE SPEED | C9: =IFERROR(+C4/C7/60,"") | E9: =IFERROR(+E4/E7/60,"") | G9: =IFERROR(+G4/G7/60,"") | I9: =IFERROR(+I4/I7/60,"") | K9: =IFERROR(+K4/K7/60,"") | M9: =IFERROR(+M4/M7/60,"") | O9: =IFERROR(+O4/O7/60,"") | R9: AVRAGE SPEED | S9: =IFERROR(+S4/S7/60,"") | U9: =IFERROR(+U4/U7/60,"") | W9: =IFERROR(+W4/W7/60,"") | Y9: =IFERROR(+Y4/Y7/60,"") | AA9: =IFERROR(+AA4/AA7/60,"") | AC9: =IFERROR(+AC4/AC7/60,"") | AE9: =IFERROR(+AE4/AE7/60,"") | AG9: =IFERROR(+AG4/AG7/60,"") | AI9: =IFERROR(+AI4/AI7/60,"") | AK9: =IFERROR(+AK4/AK7/60,"") | AN9: AVRAGE SPEED | AO9: =+AO4/AO7/60 -> #REF! | AQ9: =+AQ4/AQ7/60 -> #REF!
B10: TOTAL HRS | C10: =24*31 -> 744 | E10: =24*31 -> 744 | G10: =24*31 -> 744 | I10: =24*31 -> 744 | K10: =24*31 -> 744 | M10: =24*31 -> 744 | O10: =24*31 -> 744 | R10: TOTAL HRS | S10: =24*31 -> 744 | U10: =24*31 -> 744 | W10: =24*31 -> 744 | Y10: =24*31 -> 744 | AA10: =24*31 -> 744 | AC10: =24*31 -> 744 | AE10: =24*31 -> 744 | AG10: =24*31 -> 744 | AI10: =24*31 -> 744 | AK10: =24*31 -> 744 | AN10: TOTAL HRS | AO10: =24*31 -> 744 | AQ10: =24*31 -> 744
A11: 4 | B11: ENGG. STOPPAGES | Q11: 4 | R11: ENGG. STOPPAGES | AM11: 4 | AN11: ENGG. STOPPAGES
B12: HOURS & % | C12: HRS | D12: % AGE | E12: HRS | F12: % AGE | G12: HRS | H12: % AGE | I12: HRS | J12: % AGE | K12: HRS | L12: % AGE | M12: HRS | N12: % AGE | O12: HRS | P12: % AGE | R12: HOURS & % | S12: HRS | T12: % AGE | U12: HRS | V12: % AGE | W12: HRS | X12: % AGE | Y12: HRS | Z12: % AGE | AA12: HRS | AB12: % AGE | AC12: HRS | AD12: % AGE | AE12: HRS | AF12: % AGE | AG12: HRS | AH12: % AGE | AI12: HRS | AJ12: % AGE | AK12: HRS | AL12: % AGE | AN12: HOURS & % | AO12: HRS | AP12: % AGE | AQ12: HRS | AR12: % AGE
B13: Mechanical | C13: ='Osthoff-1'!$K$35 -> 0 | D13: =C13*100/C10 -> 0 | E13: ='Osthoff-2'!$K$35 -> 0 | F13: =E13*100/E10 -> 0 | G13: =PTR!$K$35 -> 0 | H13: =G13*100/G10 -> 0 | I13: =Perble!$K$35 -> 0 | J13: =+I13*100/I10 -> 0 | K13: ='Merceriser-1'!$K$35 -> 0 | L13: =K13*100/K10 -> 0 | M13: ='Merceriser-2'!$K$35 -> 0 | N13: =M13*100/M10 -> 0 | O13: =NPS!$K$35 -> 0 | P13: =O13*100/O10 -> 0 | R13: Mechanical | S13: ='Xetma-2'!$K$35 -> 0 | T13: =S13*100/S10 -> 0 | U13: ='Xetma-3'!$K$35 -> 0 | V13: =U13*100/U10 -> 0 | W13: ='Lafer-1'!$K$35 -> 0 | X13: =+W13*100/W10 -> 0 | Y13: ='Lafer-2'!$K$35 -> 0 | Z13: =+Y13*100/Y10 -> 0 | AA13: ='Lafer-3'!$K$35 -> 0 | AB13: =+AA13*100/AA10 -> 0 | AC13: ='Lafer-4'!$K$35 -> 0 | AD13: =+AC13*100/AC10 -> 0 | AE13: ='Lafer-5-Raising'!$K$35 -> 0 | AF13: =AE13*100/AE10 -> 0 | AG13: ='Lafer-5-Shearing'!$K$35 -> 0 | AH13: =AG13*100/AG10 -> 0 | AI13: ='Lafer-4'!$K$35 -> 0 | AJ13: =+AI13*100/AI10 -> 0 | AK13: =Soaper!$K$35 -> 0 | AL13: =+AK13*100/AK10 -> 0 | AN13: Mechanical | AO13: =+#REF! -> #REF! | AP13: =AO13*100/AO10 -> #REF! | AQ13: =+#REF! -> #REF! | AR13: =AQ13*100/AQ10 -> #REF!
B14: Electrical | C14: ='Osthoff-1'!$L$35 -> 0 | D14: =C14*100/C10 -> 0 | E14: ='Osthoff-2'!$L$35 -> 0 | F14: =E14*100/E10 -> 0 | G14: =PTR!$L$35 -> 0 | H14: =G14*100/G10 -> 0 | I14: =Perble!$L$35 -> 0 | J14: =+I14*100/I10 -> 0 | K14: ='Merceriser-1'!$L$35 -> 0 | L14: =K14*100/K10 -> 0 | M14: ='Merceriser-2'!$L$35 -> 0 | N14: =M14*100/M10 -> 0 | O14: =NPS!$L$35 -> 0 | P14: =O14*100/O10 -> 0 | R14: Electrical | S14: ='Xetma-2'!$L$35 -> 0 | T14: =S14*100/S10 -> 0 | U14: ='Xetma-3'!$L$35 -> 0 | V14: =U14*100/U10 -> 0 | W14: ='Lafer-1'!$L$35 -> 0 | X14: =+W14*100/W10 -> 0 | Y14: ='Lafer-2'!$L$35 -> 0 | Z14: =+Y14*100/Y10 -> 0 | AA14: ='Lafer-3'!$L$35 -> 0 | AB14: =+AA14*100/AA10 -> 0 | AC14: ='Lafer-4'!$L$35 -> 0 | AD14: =+AC14*100/AC10 -> 0 | AE14: ='Lafer-5-Raising'!$L$35 -> 0 | AF14: =AE14*100/AE10 -> 0 | AG14: ='Lafer-5-Shearing'!$L$35 -> 0 | AH14: =AG14*100/AG10 -> 0 | AI14: ='Lafer-4'!$L$35 -> 0 | AJ14: =+AI14*100/AI10 -> 0 | AK14: =Soaper!$L$35 -> 0 | AL14: =+AK14*100/AK10 -> 0 | AN14: Electrical | AO14: =+#REF! -> #REF! | AP14: =AO14*100/AO10 -> #REF! | AQ14: =+#REF! -> #REF! | AR14: =AQ14*100/AQ10 -> #REF!
B15: TOTAL | C15: =SUM(C13:C14) -> 0 | D15: =SUM(D13:D14) -> 0 | E15: =SUM(E13:E14) -> 0 | F15: =SUM(F13:F14) -> 0 | G15: =SUM(G13:G14) -> 0 | H15: =SUM(H13:H14) -> 0 | I15: =SUM(I13:I14) -> 0 | J15: =SUM(J13:J14) -> 0 | ... P15: =SUM(P13:P14) -> 0 | R15: TOTAL | S15: =SUM(S13:S14) -> 0 | T15: =SUM(T13:T14) -> 0 | U15: =SUM(U13:U14) -> 0 | V15: =SUM(V13:V14) -> 0 | W15: =SUM(W13:W14) -> 0 | X15: =SUM(X13:X14) -> 0 | Y15: =SUM(Y13:Y14) -> 0 | Z15: =SUM(Z13:Z14) -> 0 | ... AL15: =SUM(AL13:AL14) -> 0 | AN15: TOTAL | AO15: =SUM(AO13:AO14) -> #REF! | AP15: =SUM(AP13:AP14) -> #REF! | AQ15: =SUM(AQ13:AQ14) -> #REF! | AR15: =SUM(AR13:AR14) -> #REF!
A17: 5 | B17: REASONS FOR | Q17: 5 | R17: REASONS FOR | AM17: 5 | AN17: REASONS FOR
B18: STOPPAGES | R18: STOPPAGES | AN18: STOPPAGES
B20: 1)ENGG. STOPPAGES | R20: 1)ENGG. STOPPAGES | AN20: 1)ENGG. STOPPAGES
C21: HRS | D21: % AGE | E21: HRS | F21: % AGE | G21: HRS | H21: % AGE | I21: HRS | J21: % AGE | K21: HRS | L21: % AGE | M21: HRS | N21: % AGE | O21: HRS | P21: % AGE | S21: HRS | T21: % AGE | U21: HRS | V21: % AGE | W21: HRS | X21: % AGE | Y21: HRS | Z21: % AGE | AA21: HRS | AB21: % AGE | AC21: HRS | AD21: % AGE | AE21: HRS | AF21: % AGE | AG21: HRS | AH21: % AGE | AI21: HRS | AJ21: % AGE | AK21: HRS | AL21: % AGE | AO21: HRS | AP21: % AGE | AQ21: HRS | AR21: % AGE
B22: MECH. BREAKDOWN | C22: ='Osthoff-1'!$K$35 -> 0 | D22: =C22*100/C10 -> 0 | E22: ='Osthoff-2'!$K$35 -> 0 | F22: =E22*100/E10 -> 0 | G22: =PTR!$K$35 -> 0 | H22: =G22*100/G10 -> 0 | I22: =Perble!$K$35 -> 0 | J22: =+I22/I10*100 -> 0 | K22: ='Merceriser-1'!$K$35 -> 0 | L22: =K22*100/K10 -> 0 | M22: ='Merceriser-2'!$K$35 -> 0 | N22: =M22*100/M10 -> 0 | O22: =NPS!K35 -> 0 | P22: =O22*100/O10 -> 0 | R22: MECH. BREAKDOWN | S22: ='Xetma-2'!$K$35 -> 0 | T22: =S22*100/S10 -> 0 | U22: ='Xetma-3'!$K$35 -> 0 | V22: =U22*100/U10 -> 0 | W22: ='Lafer-1'!$K$35 -> 0 | X22: =+W22*100/W10 -> 0 | Y22: ='Lafer-2'!$K$35 -> 0 | Z22: =+Y22*100/Y10 -> 0 | AA22: ='Lafer-3'!$K$35 -> 0 | AB22: =+AA22*100/AA10 -> 0 | AC22: ='Lafer-4'!$K$35 -> 0 | AD22: =+AC22*100/AC10 -> 0 | AE22: ='Lafer-5-Raising'!$K$35 -> 0 | AF22: =AE22*100/AE10 -> 0 | AG22: ='Lafer-5-Shearing'!$K$35 -> 0 | AH22: =AG22*100/AG10 -> 0 | AI22: ='Lafer-4'!$K$35 -> 0 | AJ22: =+AI22*100/AI10 -> 0 | AK22: =Soaper!$K$35 -> 0 | AL22: =+AK22*100/AK10 -> 0 | AN22: MECH. BREAKDOWN | AO22: =+#REF! -> #REF! | AP22: =AO22*100/AO10 -> #REF! | AQ22: =+#REF! -> #REF! | AR22: =AQ22*100/AQ10 -> #REF!
B23: ELECT. BREAKDOWN | C23: ='Osthoff-1'!L35 -> 0 | D23: =C23*100/C10 -> 0 | E23: ='Osthoff-1'!$L$35 -> 0 | F23: =E23*100/E10 -> 0 | G23: =PTR!$L$35 -> 0 | H23: =G23*100/G10 -> 0 | I23: =Perble!L35 -> 0 | J23: =+I23/I10*100 -> 0 | K23: ='Merceriser-1'!L35 -> 0 | L23: =K23*100/K10 -> 0 | M23: ='Merceriser-2'!L35 -> 0 | N23: =M23*100/M10 -> 0 | O23: =NPS!L35 -> 0 | P23: =O23*100/O10 -> 0 | R23: ELECT. BREAKDOWN | S23: ='Xetma-2'!L35 -> 0 | T23: =S23*100/S10 -> 0 | U23: ='Xetma-3'!$L$35 -> 0 | V23: =U23*100/U10 -> 0 | W23: ='Lafer-1'!$L$35 -> 0 | X23: =+W23*100/W10 -> 0 | Y23: ='Lafer-2'!$L$35 -> 0 | Z23: =+Y23*100/Y10 -> 0 | AA23: ='Lafer-3'!$L$35 -> 0 | AB23: =+AA23*100/AA10 -> 0 | AC23: ='Lafer-4'!$L$35 -> 0 | AD23: =+AC23*100/AC10 -> 0 | AE23: ='Lafer-5-Raising'!$L$35 -> 0 | AF23: =AE23*100/AE10 -> 0 | AG23: ='Lafer-5-Shearing'!$L$35 -> 0 | AH23: =AG23*100/AG10 -> 0 | AI23: ='Lafer-4'!$L$35 -> 0 | AJ23: =+AI23*100/AI10 -> 0 | AK23: =Soaper!$L$35 -> 0 | AL23: =+AK23*100/AK10 -> 0 | AN23: ELECT. BREAKDOWN | AO23: =+#REF! -> #REF! | AP23: =AO23*100/AO10 -> #REF! | AQ23: =+#REF! -> #REF! | AR23: =AQ23*100/AQ10 -> #REF!
B24: MECH. MAINTAINENCE | C24: ='Osthoff-1'!$O$35 -> 0 | D24: =C24*100/C10 -> 0 | E24: ='Osthoff-2'!$O$35 -> 0 | F24: =E24*100/E10 -> 0 | G24: =PTR!$O$35 -> 0 | H24: =G24*100/G10 -> 0 | I24: =Perble!$O$35 -> 0 | J24: =+I24/I10*100 -> 0 | K24: ='Merceriser-1'!O35 -> 0 | L24: =K24*100/K10 -> 0 | M24: ='Merceriser-2'!O35 -> 0 | N24: =M24*100/M10 -> 0 | O24: =NPS!O35 -> 0 | P24: =O24*100/O10 -> 0 | R24: MECH. MAINTAINENCE | S24: ='Xetma-2'!O35 -> 0 | T24: =S24*100/S10 -> 0 | U24: ='Xetma-3'!$O$35 -> 0 | V24: =U24*100/U10 -> 0 | W24: ='Lafer-1'!$O$35 -> 0 | X24: =+W24*100/W10 -> 0 | Y24: ='Lafer-2'!$O$35 -> 0 | Z24: =+Y24*100/Y10 -> 0 | AA24: ='Lafer-3'!$O$35 -> 0 | AB24: =+AA24*100/AA10 -> 0 | AC24: ='Lafer-4'!$O$35 -> 0 | AD24: =+AC24*100/AC10 -> 0 | AE24: ='Lafer-5-Raising'!$O$35 -> 0 | AF24: =AE24*100/AE10 -> 0 | AG24: ='Lafer-5-Shearing'!$O$35 -> 0 | AH24: =AG24*100/AG10 -> 0 | AI24: ='Lafer-4'!$O$35 -> 0 | AJ24: =+AI24*100/AI10 -> 0 | AK24: =Soaper!$O$35 -> 0 | AL24: =+AK24*100/AK10 -> 0 | AN24: MECH. MAINTAINENCE | AO24: =+#REF! -> #REF! | AP24: =AO24*100/AO10 -> #REF! | AQ24: =+#REF! -> #REF! | AR24: =AQ24*100/AQ10 -> #REF!
B25: NO POWER | C25: ='Osthoff-1'!$P$35 -> 0 | D25: =C25*100/C10 -> 0 | E25: ='Osthoff-2'!$P$35 -> 0 | F25: =E25*100/E10 -> 0 | G25: =PTR!$P$35 -> 0 | H25: =G25*100/G10 -> 0 | I25: =Perble!$P$35 -> 0 | J25: =+I25/I10*100 -> 0 | K25: ='Merceriser-1'!P35 -> 0 | L25: =+K25/K10 -> 0 | M25: ='Merceriser-2'!P35 -> 0 | N25: =+M25/M10*100 -> 0 | O25: =NPS!P35 -> 0 | P25: =O25*100/O10 -> 0 | R25: NO POWER | S25: ='Xetma-2'!P35 -> 0 | T25: =S25*100/S10 -> 0 | U25: ='Xetma-3'!$P$35 -> 0 | V25: =U25*100/U10 -> 0 | W25: ='Lafer-1'!$P$35 -> 0 | X25: =+W25*100/W10 -> 0 | Y25: ='Lafer-2'!$P$35 -> 0 | Z25: =+Y25*100/Y10 -> 0 | AA25: ='Lafer-3'!$P$35 -> 0 | AB25: =+AA25*100/AA10 -> 0 | AC25: ='Lafer-4'!$P$35 -> 0 | AD25: =+AC25*100/AC10 -> 0 | AE25: ='Lafer-5-Raising'!$P$35 -> 0 | AF25: =AE25*100/AE10 -> 0 | AG25: ='Lafer-5-Shearing'!$P$35 -> 0 | AH25: =AG25*100/AG10 -> 0 | AI25: ='Lafer-4'!$P$35 -> 0 | AJ25: =+AI25*100/AI10 -> 0 | AK25: =Soaper!$P$35 -> 0 | AL25: =+AK25*100/AK10 -> 0 | AN25: NO POWER | AO25: =+#REF! -> #REF! | AP25: =AO25*100/AO10 -> #REF! | AQ25: =+#REF! -> #REF! | AR25: =AQ25*100/AQ10 -> #REF!
B26: NO STEAM | C26: ='Osthoff-1'!$Q$35 -> 0 | D26: =C26*100/C10 -> 0 | E26: ='Osthoff-2'!$Q$35 -> 0 | F26: =E26*100/E10 -> 0 | G26: =PTR!$Q$35 -> 0 | H26: =G26*100/G10 -> 0 | I26: =Perble!$Q$35 -> 0 | J26: =+I26/I10*100 -> 0 | K26: ='Merceriser-1'!Q35 -> 0 | L26: =K26*100/K10 -> 0 | M26: ='Merceriser-2'!Q35 -> 0 | N26: =M26*100/M10 -> 0 | O26: =[1]NPS!Q35 -> 0 | P26: =O26*100/O10 -> 0 | R26: NO STEAM | S26: ='Xetma-2'!Q35 -> 0 | T26: =S26*100/S10 -> 0 | U26: ='Xetma-3'!$Q$35 -> 0 | V26: =U26*100/U10 -> 0 | W26: ='Lafer-1'!$Q$35 -> 0 | X26: =+W26*100/W10 -> 0 | Y26: ='Lafer-2'!$Q$35 -> 0 | Z26: =+Y26*100/Y10 -> 0 | AA26: ='Lafer-3'!$Q$35 -> 0 | AB26: =+AA26*100/AA10 -> 0 | AC26: ='Lafer-4'!$Q$35 -> 0 | AD26: =+AC26*100/AC10 -> 0 | AE26: ='Lafer-5-Raising'!$Q$35 -> 0 | AF26: =AE26*100/AE10 -> 0 | AG26: ='Lafer-5-Shearing'!$Q$35 -> 0 | AH26: =AG26*100/AG10 -> 0 | AI26: ='Lafer-4'!$Q$35 -> 0 | AJ26: =+AI26*100/AI10 -> 0 | AK26: =Soaper!$Q$35 -> 0 | AL26: =+AK26*100/AK10 -> 0 | AN26: NO STEAM | AO26: =+#REF! -> #REF! | AP26: =AO26*100/AO10 -> #REF! | AQ26: =+#REF! -> #REF! | AR26: =AQ26*100/AQ10 -> #REF!
R27: CHANGE OVER FOR BRUSHING | AN27: CHANGE OVER FOR BRUSHING
B28: TOTAL | C28: =SUM(C22:C26) -> 0 | D28: =SUM(D22:D26) -> 0 | E28: =SUM(E22:E26) -> 0 | F28: =SUM(F22:F26) -> 0 | G28: =SUM(G22:G26) -> 0 | H28: =SUM(H22:H26) -> 0 | I28: =SUM(I22:I26) -> 0 | J28: =100/I10*I28 -> 0 | K28: =SUM(K22:K26) -> 0 | L28: =+K28*100/K10 -> 0 | M28: =SUM(M22:M26) -> 0 | N28: =SUM(N22:N26) -> 0 | O28: =SUM(O22:O26) -> 0 | P28: =SUM(P22:P26) -> 0 | R28: TOTAL | S28: =SUM(S22:S26) -> 0 | T28: =SUM(T22:T26) -> 0 | U28: =SUM(U22:U26) -> 0 | V28: =SUM(V22:V26) -> 0 | W28: =SUM(W22:W26) -> 0 | X28: =SUM(X22:X27) -> 0 | Y28: =SUM(Y22:Y26) -> 0 | Z28: =SUM(Z22:Z27) -> 0 | AA28: =SUM(AA22:AA26) -> 0 | AB28: =SUM(AB22:AB27) -> 0 | AC28: =SUM(AC22:AC26) -> 0 | AD28: =SUM(AD22:AD27) -> 0 | AE28: =SUM(AE22:AE26) -> 0 | AF28: =SUM(AF22:AF26) -> 0 | AG28: =SUM(AG22:AG26) -> 0 | AH28: =SUM(AH22:AH26) -> 0 | AI28: =SUM(AI22:AI26) -> 0 | AJ28: =SUM(AJ22:AJ26) -> 0 | AK28: =SUM(AK22:AK26) -> 0 | AL28: =SUM(AL22:AL26) -> 0 | AN28: TOTAL | AO28: =SUM(AO22:AO26) -> #REF! | AP28: =SUM(AP22:AP26) -> #REF! | AQ28: =SUM(AQ22:AQ26) -> #REF! | AR28: =SUM(AR22:AR26) -> #REF!
B30: 2) PROCESS | R30: 2) PROCESS | AN30: 2) PROCESS
B31: STOPPAGES | R31: STOPPAGES | AN31: STOPPAGES
C32: HRS | D32: % AGE | E32: HRS | F32: % AGE | G32: HRS | H32: % AGE | I32: HRS | J32: % AGE | K32: HRS | L32: % AGE | M32: HRS | N32: % AGE | O32: HRS | P32: % AGE | S32: HRS | T32: % AGE | U32: HRS | V32: % AGE | W32: HRS | X32: % AGE | Y32: HRS | Z32: % AGE | AA32: HRS | AB32: % AGE | AC32: HRS | AD32: % AGE | AE32: HRS | AF32: % AGE | AG32: HRS | AH32: % AGE | AI32: HRS | AJ32: % AGE | AK32: HRS | AL32: % AGE | AO32: HRS | AP32: % AGE | AQ32: HRS | AR32: % AGE
B33: M/C CLEANING | C33: ='Osthoff-1'!$M$35 -> 0 | D33: =C33*100/C10 -> 0 | E33: ='Osthoff-2'!$M$35 -> 0 | F33: =E33*100/E10 -> 0 | G33: =PTR!$M$35 -> 0 | H33: =G33*100/G10 -> 0 | I33: =Perble!$M$35 -> 0 | J33: =100/I10*I33 -> 0 | K33: ='Merceriser-1'!M35 -> 0 | L33: =K33*100/K10 -> 0 | M33: ='Merceriser-2'!M35 -> 0 | N33: =M33*100/M10 -> 0 | O33: =NPS!M35 -> 0 | P33: =O33*100/O10 -> 0 | R33: M/C CLEANING | S33: ='Xetma-2'!M35 -> 0 | T33: =S33*100/S10 -> 0 | U33: ='Xetma-3'!$M$35 -> 0 | V33: =U33*100/U10 -> 0 | W33: ='Lafer-1'!$M$35 -> 0 | X33: =+W33*100/W10 -> 0 | Y33: ='Lafer-2'!$M$35 -> 0 | Z33: =+Y33*100/Y10 -> 0 | AA33: ='Lafer-3'!$M$35 -> 0 | AB33: =+AA33*100/AA10 -> 0 | AC33: ='Lafer-4'!$M$35 -> 0 | AD33: =+AC33*100/AC10 -> 0 | AE33: ='Lafer-5-Raising'!$M$35 -> 0 | AF33: =AE33*100/AE10 -> 0 | AG33: ='Lafer-5-Shearing'!$M$35 -> 0 | AH33: =AG33*100/AG10 -> 0 | AI33: ='Lafer-4'!$M$35 -> 0 | AJ33: =+AI33*100/AI10 -> 0 | AK33: =Soaper!$M$35 -> 0 | AL33: =+AK33*100/AK10 -> 0 | AN33: M/C CLEANING | AO33: =+#REF! -> #REF! | AP33: =AO33*100/AO10 -> #REF! | AQ33: =+#REF! -> #REF! | AR33: =AQ33*100/AQ10 -> #REF!
B34: QUALITY , DWELL TIME CHANGE | C34: ='Osthoff-1'!$N$35 -> 0 | D34: =C34*100/C10 -> 0 | E34: ='Osthoff-2'!$N$35 -> 0 | F34: =E34*100/E10 -> 0 | G34: =PTR!$N$35 -> 0 | H34: =G34*100/G10 -> 0 | I34: =Perble!$N$35 -> 0 | J34: =100/I10*I34 -> 0 | K34: ='Merceriser-1'!N35 -> 0 | L34: =K34*100/K10 -> 0 | M34: ='Merceriser-2'!N35 -> 0 | N34: =M34*100/M10 -> 0 | O34: =NPS!N35 -> 0 | P34: =O34*100/O10 -> 0 | R34: QUALITY , DWELL TIME CHANGE | S34: ='Xetma-2'!N35 -> 0 | T34: =S34*100/S10 -> 0 | U34: ='Xetma-3'!$N$35 -> 0 | V34: =U34*100/U10 -> 0 | W34: ='Lafer-1'!$N$35 -> 0 | X34: =+W34*100/W10 -> 0 | Y34: ='Lafer-2'!$N$35 -> 0 | Z34: =+Y34*100/Y10 -> 0 | AA34: ='Lafer-3'!$N$35 -> 0 | AB34: =+AA34*100/AA10 -> 0 | AC34: ='Lafer-4'!$N$35 -> 0 | AD34: =+AC34*100/AC10 -> 0 | AE34: ='Lafer-5-Raising'!$N$35 -> 0 | AF34: =AE34*100/AE10 -> 0 | AG34: ='Lafer-5-Shearing'!$N$35 -> 0 | AH34: =AG34*100/AG10 -> 0 | AI34: ='Lafer-4'!$N$35 -> 0 | AJ34: =+AI34*100/AI10 -> 0 | AK34: =Soaper!$N$35 -> 0 | AL34: =+AK34*100/AK10 -> 0 | AN34: QUALITY , DWELL TIME CHANGE | AO34: =+#REF! -> #REF! | AP34: =AO34*100/AO10 -> #REF! | AQ34: =+#REF! -> #REF! | AR34: =AQ34*100/AQ10 -> #REF!
B35: NO PROGRAMME | C35: ='Osthoff-1'!$R$35 -> 0 | D35: =C35*100/C10 -> 0 | E35: ='Osthoff-2'!$R$35 -> 0 | F35: =E35*100/E10 -> 0 | G35: =PTR!$R$35 -> 0 | H35: =G35*100/G10 -> 0 | I35: =Perble!$R$35 -> 0 | J35: =100/I10*I35 -> 0 | K35: ='Merceriser-1'!R35 -> 0 | L35: =K35*100/K10 -> 0 | M35: ='Merceriser-2'!R35 -> 0 | N35: =M35*100/M10 -> 0 | O35: =NPS!R35 -> 0 | P35: =O35*100/O10 -> 0 | R35: NO PROGRAMME | S35: ='Xetma-2'!R35 -> 0 | T35: =S35*100/S10 -> 0 | U35: ='Xetma-3'!$R$35 -> 0 | V35: =U35*100/U10 -> 0 | W35: ='Lafer-1'!$R$35 -> 0 | X35: =+W35*100/W10 -> 0 | Y35: ='Lafer-2'!$R$35 -> 0 | Z35: =+Y35*100/Y10 -> 0 | AA35: ='Lafer-3'!$R$35 -> 0 | AB35: =+AA35*100/AA10 -> 0 | AC35: ='Lafer-4'!$R$35 -> 0 | AD35: =+AC35*100/AC10 -> 0 | AE35: ='Lafer-5-Raising'!$R$35 -> 0 | AF35: =AE35*100/AE10 -> 0 | AG35: ='Lafer-5-Shearing'!$R$35 -> 0 | AH35: =AG35*100/AG10 -> 0 | AI35: ='Lafer-4'!$R$35 -> 0 | AJ35: =+AI35*100/AI10 -> 0 | AK35: =Soaper!$R$35 -> 0 | AL35: =+AK35*100/AK10 -> 0 | AN35: NO PROGRAMME | AO35: =+#REF! -> #REF! | AP35: =AO35*100/AO10 -> #REF! | AQ35: =+#REF! -> #REF! | AR35: =AQ35*100/AQ10 -> #REF!
B36: MAN POWER SHORTAGE | C36: ='Osthoff-1'!$S$35 -> 0 | D36: =C36*100/C10 -> 0 | E36: ='Osthoff-2'!$S$35 -> 0 | F36: =E36*100/E10 -> 0 | G36: =PTR!$S$35 -> 0 | H36: =G36*100/G10 -> 0 | I36: =Perble!$S$35 -> 0 | J36: =100/I10*I36 -> 0 | K36: ='Merceriser-1'!S35 -> 0 | L36: =+K36*100/K10 -> 0 | M36: ='Merceriser-2'!S35 -> 0 | N36: =+O36*100/M10 -> 0 | O36: =NPS!S35 -> 0 | P36: =+#REF!*100/O10 -> #REF! | R36: MAN POWER SHORTAGE | S36: ='Xetma-2'!S35 -> 0 | T36: =+S36*100/S10 -> 0 | U36: ='Xetma-3'!$S$35 -> 0 | V36: =+U36*100/U10 -> 0 | W36: ='Lafer-1'!$S$35 -> 0 | X36: =+W36*100/W10 -> 0 | Y36: ='Lafer-2'!$S$35 -> 0 | Z36: =+Y36*100/Y10 -> 0 | AA36: ='Lafer-3'!$S$35 -> 0 | AB36: =+AA36*100/AA10 -> 0 | AC36: ='Lafer-4'!$S$35 -> 0 | AD36: =+AC36*100/AC10 -> 0 | AE36: ='Lafer-5-Raising'!$S$35 -> 0 | AF36: =+AE36*100/AE10 -> 0 | AG36: ='Lafer-5-Shearing'!$S$35 -> 0 | AH36: =+AG36*100/AG10 -> 0 | AI36: ='Lafer-4'!$S$35 -> 0 | AJ36: =+AI36*100/AI10 -> 0 | AK36: =Soaper!$S$35 -> 0 | AL36: =+AK36*100/AK10 -> 0 | AN36: MAN POWER SHORTAGE | AO36: =+#REF! -> #REF! | AP36: =+AO36*100/AO10 -> #REF! | AQ36: =+#REF! -> #REF! | AR36: =+AQ36*100/AQ10 -> #REF!
B37: MISC. STOPPAGE (IN NOW OTHER OPERATIONAL FFAULT) | C37: ='Osthoff-1'!$T$35 -> 0 | D37: =C37*100/C10 -> 0 | E37: ='Osthoff-2'!$T$35 -> 0 | F37: =E37*100/E10 -> 0 | G37: =PTR!T35 -> 0 | H37: =G37*100/G10 -> 0 | I37: =Perble!$T$35 -> 0 | J37: =100/I10*I37 -> 0 | K37: ='Merceriser-1'!T35 -> 0 | L37: =K37*100/K10 -> 0 | M37: ='Merceriser-2'!T35 -> 0 | N37: =M37*100/M10 -> 0 | O37: =NPS!T35 -> 0 | P37: =O37*100/O10 -> 0 | R37: MISC. STOPPAGE (IN NOW OTHER OPERATIONAL FFAULT) | S37: ='Xetma-2'!T35 -> 0 | T37: =S37*100/S10 -> 0 | U37: ='Xetma-3'!$T$35 -> 0 | V37: =U37*100/U10 -> 0 | W37: ='Lafer-1'!$T$35 -> 0 | X37: =+W37*100/W10 -> 0 | Y37: ='Lafer-2'!$T$35 -> 0 | Z37: =+Y37*100/Y10 -> 0 | AA37: ='Lafer-3'!$T$35 -> 0 | AB37: =+AA37*100/AA10 -> 0 | AC37: ='Lafer-4'!$T$35 -> 0 | AD37: =+AC37*100/AC10 -> 0 | AE37: ='Lafer-5-Raising'!$T$35 -> 0 | AF37: =AE37*100/AE10 -> 0 | AG37: ='Lafer-5-Shearing'!$T$35 -> 0 | AH37: =AG37*100/AG10 -> 0 | AI37: ='Lafer-4'!$T$35 -> 0 | AJ37: =+AI37*100/AI10 -> 0 | AK37: =Soaper!$T$35 -> 0 | AL37: =+AK37*100/AK10 -> 0 | AN37: MISC. STOPPAGE (IN NOW OTHER OPERATIONAL FFAULT) | AO37: =+#REF! -> #REF! | AP37: =AO37*100/AO10 -> #REF! | AQ37: =+#REF! -> #REF! | AR37: =AQ37*100/AQ10 -> #REF!
B38: INSECT PROBLEM. | C38: ='Osthoff-1'!$U$35 -> 0 | D38: =C38*100/C10 -> 0 | E38: ='Osthoff-2'!$U$35 -> 0 | F38: =E38*100/E10 -> 0 | G38: =PTR!$U$35 -> 0 | H38: =G38*100/G10 -> 0 | I38: =Perble!$U$35 -> 0 | J38: =I38*100/I10 -> 0 | K38: ='Merceriser-1'!U35 -> 0 | L38: =K38*100/K10 -> 0 | M38: ='Merceriser-2'!U35 -> 0 | N38: =M38*100/M10 -> 0 | O38: =NPS!U35 -> 0 | P38: =O38*100/O10 -> 0 | R38: INSECT PROBLEM. | S38: ='Xetma-2'!U35 -> 0 | T38: =S38*100/S10 -> 0 | U38: ='Xetma-3'!$U$35 -> 0 | V38: =U38*100/U10 -> 0 | W38: ='Lafer-1'!$U$35 -> 0 | X38: =W38*100/W10 -> 0 | Y38: ='Lafer-2'!$U$35 -> 0 | Z38: =Y38*100/Y10 -> 0 | AA38: ='Lafer-3'!$U$35 -> 0 | AB38: =AA38*100/AA10 -> 0 | AC38: ='Lafer-4'!$U$35 -> 0 | AD38: =AC38*100/AC10 -> 0 | AE38: ='Lafer-5-Raising'!$U$35 -> 0 | AF38: =AE38*100/AE10 -> 0 | AG38: ='Lafer-5-Shearing'!$U$35 -> 0 | AH38: =AG38*100/AG10 -> 0 | AI38: ='Lafer-4'!$U$35 -> 0 | AJ38: =AI38*100/AI10 -> 0 | AK38: =Soaper!$U$35 -> 0 | AL38: =AK38*100/AK10 -> 0 | AN38: INSECT PROBLEM. | AO38: =+#REF! -> #REF! | AP38: =AO38*100/AO10 -> #REF! | AQ38: =+#REF! -> #REF! | AR38: =AQ38*100/AQ10 -> #REF!
B39: NO TROLLEY | C39: ='Osthoff-1'!$V$35 -> 0 | D39: =C39*100/C10 -> 0 | E39: ='Osthoff-2'!$V$35 -> 0 | F39: =E39*100/E10 -> 0 | G39: =PTR!$V$35 -> 0 | H39: =G39*100/G10 -> 0 | I39: =Perble!$V$35 -> 0 | J39: =100/I10*I39 -> 0 | K39: ='Merceriser-1'!V35 -> 0 | L39: =100/K10*K39 -> 0 | M39: ='Merceriser-2'!X35 -> 0 | N39: =100/M10*M39 -> 0 | O39: =NPS!V35 -> 0 | P39: =100/O10*O39 -> 0 | R39: NO TROLLEY | S39: ='Xetma-2'!V35 -> 0 | T39: =100/S10*S39 -> 0 | U39: ='Xetma-3'!$V$35 -> 0 | V39: =100/U10*U39 -> 0 | W39: ='Lafer-1'!$V$35 -> 0 | X39: =100/W10*W39 -> 0 | Y39: ='Lafer-2'!$V$35 -> 0 | Z39: =100/Y10*Y39 -> 0 | AA39: ='Lafer-3'!$V$35 -> 0 | AB39: =100/AA10*AA39 -> 0 | AC39: ='Lafer-4'!$V$35 -> 0 | AD39: =100/AC10*AC39 -> 0 | AE39: ='Lafer-5-Raising'!$V$35 -> 0 | AF39: =100/AE10*AE39 -> 0 | AG39: ='Lafer-5-Shearing'!$V$35 -> 0 | AH39: =100/AG10*AG39 -> 0 | AI39: ='Lafer-4'!$V$35 -> 0 | AJ39: =100/AI10*AI39 -> 0 | AK39: =Soaper!$V$35 -> 0 | AL39: =100/AK10*AK39 -> 0 | AN39: NO TROLLEY | AO39: =+#REF! -> #REF! | AP39: =100/AO10*AO39 -> #REF! | AQ39: =+#REF! -> #REF! | AR39: =100/AQ10*AQ39 -> #REF!
B40: TOTAL | C40: =SUM(C33:C39) -> 0 | D40: =SUM(D33:D39) -> 0 | E40: =SUM(E33:E39) -> 0 | F40: =SUM(F33:F39) -> 0 | G40: =SUM(G33:G39) -> 0 | H40: =SUM(H33:H39) -> 0 | I40: =SUM(I33:I39) -> 0 | J40: =SUM(J33:J39) -> 0 | ... P40: =SUM(P33:P39) -> #REF! | R40: TOTAL | S40: =SUM(S33:S39) -> 0 | T40: =SUM(T33:T39) -> 0 | U40: =SUM(U33:U39) -> 0 | V40: =SUM(V33:V39) -> 0 | W40: =SUM(W33:W39) -> 0 | X40: =SUM(X33:X39) -> 0 | Y40: =SUM(Y33:Y39) -> 0 | Z40: =SUM(Z33:Z39) -> 0 | ... AL40: =SUM(AL33:AL39) -> 0 | AN40: TOTAL | AO40: =SUM(AO33:AO39) -> #REF! | AP40: =SUM(AP33:AP39) -> #REF! | AQ40: =SUM(AQ33:AQ39) -> #REF! | AR40: =SUM(AR33:AR39) -> #REF!
B43: REPROCESS , MTRS | C43: ='Osthoff-1'!D345 -> 0 | E43: ='Osthoff-2'!D35 -> 0 | G43: =PTR!D35 -> 0 | I43: =Perble!D35 -> 0 | K43: ='Merceriser-1'!D35 -> 0 | M43: ='Merceriser-2'!D35 -> 0 | O43: =NPS!D35 -> 0 | R43: REPROCESS , MTRS | S43: ='Xetma-2'!D35 -> 0 | U43: ='Xetma-3'!$H$35 -> 0 | W43: ='Lafer-1'!$H$35 -> 0 | Y43: ='Lafer-2'!$H$35 -> 0 | AA43: ='Lafer-3'!$H$35 -> 0 | AC43: ='Lafer-4'!$H$35 -> 0 | AE43: ='Lafer-5-Raising'!$H$35 -> 0 | AG43: ='Lafer-5-Shearing'!$H$35 -> 0 | AI43: ='Lafer-4'!$H$35 -> 0 | AK43: =Soaper!$H$35 -> 0 | AN43: REPROCESS , MTRS | AO43: =+#REF! -> #REF! | AQ43: =+#REF! -> #REF!
B44: REPROCESS % | C44: =+C43/C4*100 -> #DIV/0! | E44: =+E43/E4*100 -> #DIV/0! | G44: =+G43/G4*100 -> #DIV/0! | I44: =+I43/I4*100 -> #DIV/0! | K44: =IFERROR(+K43/K4*100,"") | L44: =IFERROR(+L43/L4*100,"") | M44: =IFERROR(+M43/M4*100,"") | N44: =IFERROR(+N43/N4*100,"") | O44: =IFERROR(+O43/O4*100,"") | P44: =IFERROR(+P43/P4*100,"") | Q44: =IFERROR(+Q43/Q4*100,"") -> 0 | R44: =IFERROR(+R43/R4*100,"") | ... AL44: =IFERROR(+AL43/AL4*100,"") | AN44: REPROCESS % | AO44: =+AO43/AO4*100 -> #REF! | AQ44: =+AQ43/AQ4*100 -> #REF!
B45: REASONS FOR REPROCESS | C45: PROBLEM | D45: MTS/ %AGE | E45: PROBLEM | F45: MTS/ %AGE | G45: PROBLEM | H45: MTS/ %AGE | I45: PROBLEM | J45: MTS/ %AGE | K45: PROBLEM | L45: MTS/ %AGE | M45: PROBLEM | N45: MTS/ %AGE | O45: PROBLEM | P45: MTS/ %AGE | R45: REASONS FOR REPROCESS | S45: PROBLEM | T45: MTS/ %AGE | U45: PROBLEM | V45: MTS/ %AGE | W45: PROBLEM | X45: MTS/ %AGE | Y45: PROBLEM | Z45: MTS/ %AGE | AA45: PROBLEM | AB45: MTS/ %AGE | AC45: PROBLEM | AD45: MTS/ %AGE | AE45: PROBLEM | AF45: MTS/ %AGE | AG45: PROBLEM | AH45: MTS/ %AGE | AI45: PROBLEM | AJ45: MTS/ %AGE | AK45: PROBLEM | AL45: MTS/ %AGE | AN45: REASONS FOR REPROCESS | AO45: PROBLEM | AP45: MTS/ %AGE | AQ45: PROBLEM | AR45: MTS/ %AGE
C51: =C40+C28+C7 -> 0 | D51: =D40+D28+C8 -> 0 | E51: =E40+E28+E7 -> 0 | F51: =F40+F28+E8 -> 0 | G51: =G40+G28+G7 -> 0 | H51: =H40+H28+G8 -> 0 | I51: =I40+I28+I7 -> 0 | J51: =+J40+J28+I8 -> 0 | K51: =K40+K28+K7 -> 0 | L51: =+L40+L28+K8 -> 0 | M51: =M40+M28+M7 -> 0 | N51: =+N40+N28+M8 -> 0 | O51: =O40+O28+O7 -> 0 | P51: =+P40+P28+O8 -> #REF! | S51: =S40+S28+S7 -> 0 | T51: =+T40+T28+S8 -> 0 | U51: =U40+U28+U7 -> 0 | V51: =+V40+V28+U8 -> 0 | W51: =W40+W28+W7 -> 0 | X51: =+X40+X28+W8 -> 0 | Y51: =Y40+Y28+Y7 -> 0 | Z51: =+Z40+Z28+Y8 -> 0 | AA51: =AA40+AA28+AA7 -> 0 | AB51: =+AB40+AB28+AA8 -> 0 | AC51: =AC40+AC28+AC7 -> 0 | AD51: =+AD40+AD28+AC8 -> 0 | AE51: =AE40+AE28+AE7 -> 0 | AF51: =+AF40+AF28+AE8 -> 0 | AG51: =AG40+AG28+AG7 -> 0 | AH51: =+AH40+AH28+AG8 -> 0 | AI51: =AI40+AI28+AI7 -> 0 | AJ51: =+AJ40+AJ28+AI8 -> 0 | AK51: =AK40+AK28+AK7 -> 0 | AL51: =+AL40+AL28+AK8 -> 0 | AO51: =+AO40+AO28+AO7 -> #REF! | AP51: =+AP40+AP28+AO8 -> #REF! | AQ51: =+AQ40+AQ28+AQ7 -> #REF! | AR51: =+AR40+AR28+AQ8 -> #REF!
...

Sheet XETMA-1
A1: XETMA-1 PRODUCTION | J1: =+#REF! -> #REF!
A3: Date | B3: Total prod. | C3: Process Demand | D3: Re-process | E3: Effective Production | F3: Mtd. prod. | G3: Prod. kg | H3: Mtd. prod. kg. | I3: Running Hours | J3: Mtd. Running Hours | K3: Mechnical | L3: Electrical | M3: Machine Cleaning | N3: Change Over | O3: P.M. | P3: No. power | Q3: No.Steam | R3: No. programe | S3: Man Power Shortage | T3: Mise(Other Opration Faults) | U3: Insect problem | V3: No. Trolley | W3: Total
A4: =+#REF! -> #REF! | B4: 0 | C4: 0 | D4: 0 | E4: =+B4-D4-C4 -> 0 | F4: =+E4 -> 0 | G4: =+B4*0.245 -> 0 | H4: =+G4 -> 0 | I4: 0 | J4: 0 | R4: 24 | W4: =SUM(K4:V4) -> 24 | X4: =24-W4 -> 0
A5: =+#REF! -> #REF! | B5: 0 | C5: 0 | D5: 0 | E5: =+B5-D5-C5 -> 0 | F5: =+F4+E5 -> 0 | G5: =+B5*0.245 -> 0 | H5: =+G5+H4 -> 0 | I5: 0 | J5: =+J4+I5 -> 0 | R5: 24 | W5: =SUM(K5:V5) -> 24 | X5: =24-W5 -> 0
A6: =+#REF! -> #REF! | B6: 0 | C6: 0 | D6: 0 | E6: =+B6-D6-C6 -> 0 | F6: =+F5+E6 -> 0 | G6: =+B6*0.245 -> 0 | H6: =+G6+H5 -> 0 | I6: 0 | J6: =+J5+I6 -> 0 | R6: 24 | W6: =SUM(K6:V6) -> 24 | X6: =24-W6 -> 0
A7: =+#REF! -> #REF! | B7: 0 | C7: 0 | D7: 0 | E7: =+B7-D7-C7 -> 0 | F7: =+F6+E7 -> 0 | G7: =+B7*0.245 -> 0 | H7: =+G7+H6 -> 0 | I7: 0 | J7: =+J6+I7 -> 0 | R7: 24 | W7: =SUM(K7:V7) -> 24 | X7: =24-W7 -> 0
A8: =+#REF! -> #REF! | B8: 0 | C8: 0 | D8: 0 | E8: =+B8-D8-C8 -> 0 | F8: =+F7+E8 -> 0 | G8: =+B8*0.245 -> 0 | H8: =+G8+H7 -> 0 | I8: 0 | J8: =+J7+I8 -> 0 | R8: 24 | W8: =SUM(K8:V8) -> 24 | X8: =24-W8 -> 0
A9: =+#REF! -> #REF! | B9: 0 | C9: 0 | D9: 0 | E9: =+B9-D9-C9 -> 0 | F9: =+F8+E9 -> 0 | G9: =+B9*0.245 -> 0 | H9: =+G9+H8 -> 0 | I9: 0 | J9: =+J8+I9 -> 0 | R9: 24 | W9: =SUM(K9:V9) -> 24 | X9: =24-W9 -> 0
A10: =+#REF! -> #REF! | B10: 0 | C10: 0 | D10: 0 | E10: =+B10-D10-C10 -> 0 | F10: =+F9+E10 -> 0 | G10: =+B10*0.245 -> 0 | H10: =+G10+H9 -> 0 | I10: 0 | J10: =+J9+I10 -> 0 | R10: 24 | W10: =SUM(K10:V10) -> 24 | X10: =24-W10 -> 0
A11: =+#REF! -> #REF! | B11: 0 | C11: 0 | D11: 0 | E11: =+B11-D11-C11 -> 0 | F11: =+F10+E11 -> 0 | G11: =+B11*0.245 -> 0 | H11: =+G11+H10 -> 0 | I11: 0 | J11: =+J10+I11 -> 0 | R11: 24 | W11: =SUM(K11:V11) -> 24 | X11: =24-W11 -> 0
A12: =+#REF! -> #REF! | B12: 0 | C12: 0 | D12: 0 | E12: =+B12-D12-C12 -> 0 | F12: =+F11+E12 -> 0 | G12: =+B12*0.245 -> 0 | H12: =+G12+H11 -> 0 | I12: 0 | J12: =+J11+I12 -> 0 | R12: 24 | W12: =SUM(K12:V12) -> 24 | X12: =24-W12 -> 0
A13: =+#REF! -> #REF! | B13: 0 | C13: 0 | D13: 0 | E13: =+B13-D13-C13 -> 0 | F13: =+F12+E13 -> 0 | G13: =+B13*0.245 -> 0 | H13: =+G13+H12 -> 0 | I13: 0 | J13: =+J12+I13 -> 0 | R13: 24 | W13: =SUM(K13:V13) -> 24 | X13: =24-W13 -> 0
A14: =+#REF! -> #REF! | B14: 0 | C14: 0 | D14: 0 | E14: =+B14-D14-C14 -> 0 | F14: =+F13+E14 -> 0 | G14: =+B14*0.245 -> 0 | H14: =+G14+H13 -> 0 | I14: 0 | J14: =+J13+I14 -> 0 | R14: 24 | W14: =SUM(K14:V14) -> 24 | X14: =24-W14 -> 0
A15: =+#REF! -> #REF! | B15: 0 | C15: 0 | D15: 0 | E15: =+B15-D15-C15 -> 0 | F15: =+F14+E15 -> 0 | G15: =+B15*0.245 -> 0 | H15: =+G15+H14 -> 0 | I15: 0 | J15: =+J14+I15 -> 0 | R15: 24 | W15: =SUM(K15:V15) -> 24 | X15: =24-W15 -> 0
A16: =+#REF! -> #REF! | B16: 0 | C16: 0 | D16: 0 | E16: =+B16-D16-C16 -> 0 | F16: =+F15+E16 -> 0 | G16: =+B16*0.245 -> 0 | H16: =+G16+H15 -> 0 | I16: 0 | J16: =+J15+I16 -> 0 | R16: 24 | W16: =SUM(K16:V16) -> 24 | X16: =24-W16 -> 0
... A26: =+#REF! -> #REF! | B26: 0 | C26: 0 | D26: 0 | E26: =+B26-D26-C26 -> 0 | F26: =+F25+E26 -> 0 | G26: =+B26*0.245 -> 0 | H26: =+G26+H25 -> 0 | I26: 0 | J26: =+J25+I26 -> 0 | R26: 24 | W26: =SUM(K26:V26) -> 24 | X26: =24-W26 -> 0
A27: =+#REF! -> #REF! | B27: 0 | C27: 0 | D27: 0 | E27: =+B27-D27-C27 -> 0 | F27: =+F26+E27 -> 0 | G27: =+B27*0.245 -> 0 | H27: =+G27+H26 -> 0 | I27: 0 | J27: =+J26+I27 -> 0 | R27: 24 | W27: =SUM(K27:V27) -> 24 | X27: =24-W27 -> 0 | AC27: 2.5
A28: =+#REF! -> #REF! | B28: 0 | C28: 0 | D28: 0 | E28: =+B28-D28-C28 -> 0 | F28: =+F27+E28 -> 0 | G28: =+B28*0.245 -> 0 | H28: =+G28+H27 -> 0 | I28: 0 | J28: =+J27+I28 -> 0 | R28: 24 | W28: =SUM(K28:V28) -> 24 | X28: =24-W28 -> 0
A29: =+#REF! -> #REF! | B29: 0 | C29: 0 | D29: 0 | E29: =+B29-D29-C29 -> 0 | F29: =+F28+E29 -> 0 | G29: =+B29*0.245 -> 0 | H29: =+G29+H28 -> 0 | I29: 0 | J29: =+J28+I29 -> 0 | R29: 24 | W29: =SUM(K29:V29) -> 24 | X29: =24-W29 -> 0
A30: =+#REF! -> #REF! | B30: 0 | C30: 0 | D30: 0 | E30: =+B30-D30-C30 -> 0 | F30: =+F29+E30 -> 0 | G30: =+B30*0.245 -> 0 | H30: =+G30+H29 -> 0 | I30: 0 | J30: =+J29+I30 -> 0 | R30: 24 | W30: =SUM(K30:V30) -> 24 | X30: =24-W30 -> 0
A31: =+#REF! -> #REF! | B31: 0 | C31: 0 | D31: 0 | E31: =+B31-D31-C31 -> 0 | F31: =+F30+E31 -> 0 | G31: =+B31*0.245 -> 0 | H31: =+G31+H30 -> 0 | I31: 0 | J31: =+J30+I31 -> 0 | R31: 24 | W31: =SUM(K31:V31) -> 24 | X31: =24-W31 -> 0
A32: =+#REF! -> #REF! | B32: 0 | C32: 0 | D32: 0 | E32: =+B32-D32-C32 -> 0 | F32: =+F31+E32 -> 0 | G32: =+B32*0.245 -> 0 | H32: =+G32+H31 -> 0 | I32: 0 | J32: =+J31+I32 -> 0 | R32: 24 | W32: =SUM(K32:V32) -> 24 | X32: =24-W32 -> 0
A33: =+#REF! -> #REF! | B33: 0 | C33: 0 | D33: 0 | E33: =+B33-D33-C33 -> 0 | F33: =+F32+E33 -> 0 | G33: =+B33*0.245 -> 0 | H33: =+G33+H32 -> 0 | I33: 0 | J33: =+J32+I33 -> 0 | R33: 24 | W33: =SUM(K33:V33) -> 24 | X33: =24-W33 -> 0
A34: =+#REF! -> #REF! | D34: 0 | E34: =+B34-D34-C34 -> 0 | F34: =+F33+E34 -> 0 | G34: =+B34*0.245 -> 0 | H34: =+G34+H33 -> 0 | I34: 0 | J34: =+J33+I34 -> 0 | R34: 0 | W34: =SUM(K34:V34) -> 0 | X34: =24-W34 -> 24
A35: Total | B35: =SUM(B4:B34) -> 0 | C35: =SUM(C4:C34) -> 0 | D35: =SUM(D4:D34) -> 0 | E35: =SUM(E4:E34) -> 0 | G35: =SUM(G4:G34) -> 0 | I35: =SUM(I4:I34) -> 0 | K35: =SUM(K4:K34) -> 0 | L35: =SUM(L4:L34) -> 0 | M35: =SUM(M4:M34) -> 0 | N35: =SUM(N4:N34) -> 0 | O35: =SUM(O4:O34) -> 0 | P35: =SUM(P4:P34) -> 0 | Q35: =SUM(Q4:Q34) -> 0 | R35: =SUM(R4:R34) -> 720 | ... X35: =SUM(X4:X34) -> 24
C36: Total | D36: 2nd time | E36: Effective Production | K36: Mechnical | L36: Electrical | M36: Machine Cleaning | N36: Change Over | O36: P.M. | P36: No. power | Q36: No.Steam | R36: No. programe | S36: Man Power Shortage | T36: Mise(Other Opration Faults) | U36: Insect problem | V36: No. Trolley
B37: Total Rasing | E37: =+C37-D37 -> 0
K38: Mechanical | L38: =+K35+O35+Q35 -> 0
K39: Electrical | L39: =+L35+P35 -> 0

Sheet Osthoff-1
A3: Date | B3: Total prod. | C3: Process Demand | D3: Re-process | E3: Effective Production | F3: Mtd. prod. | G3: Prod. kg | H3: Mtd. prod. kg. | I3: Running Hours | J3: Mtd. Running Hours | K3: Mechnical | L3: Electrical | M3: Machine Cleaning | N3: Change Over | O3: P.M. | P3: No. power | Q3: No.Steam | R3: No. programe | S3: Man Power Shortage | T3: Mise(Other Opration Faults) | U3: Insect problem | V3: No. Trolley | W3: Total
E4: =+B4-D4-C4 -> 0 | H4: =G4 -> 0 | W4: =SUM(K4:V4) -> 0
E5: =+B5-D5-C5 -> 0 | H5: =G5+H4 -> 0 | W5: =SUM(K5:V5) -> 0
E6: =+B6-D6-C6 -> 0 | H6: =G6+H5 -> 0 | W6: =SUM(K6:V6) -> 0
E7: =+B7-D7-C7 -> 0 | H7: =G7+H6 -> 0 | W7: =SUM(K7:V7) -> 0
E8: =+B8-D8-C8 -> 0 | H8: =G8+H7 -> 0 | W8: =SUM(K8:V8) -> 0
E9: =+B9-D9-C9 -> 0 | H9: =G9+H8 -> 0 | W9: =SUM(K9:V9) -> 0
E10: =+B10-D10-C10 -> 0 | H10: =G10+H9 -> 0 | W10: =SUM(K10:V10) -> 0
E11: =+B11-D11-C11 -> 0 | H11: =G11+H10 -> 0 | W11: =SUM(K11:V11) -> 0
E12: =+B12-D12-C12 -> 0 | H12: =G12+H11 -> 0 | W12: =SUM(K12:V12) -> 0
E13: =+B13-D13-C13 -> 0 | H13: =G13+H12 -> 0 | W13: =SUM(K13:V13) -> 0
E14: =+B14-D14-C14 -> 0 | H14: =G14+H13 -> 0 | W14: =SUM(K14:V14) -> 0
E15: =+B15-D15-C15 -> 0 | H15: =G15+H14 -> 0 | W15: =SUM(K15:V15) -> 0
E16: =+B16-D16-C16 -> 0 | H16: =G16+H15 -> 0 | W16: =SUM(K16:V16) -> 0
... E34: =+B34-D34-C34 -> 0 | H34: =G34+H33 -> 0 | W34: =SUM(K34:V34) -> 0
A35: Total | B35: =SUM(B4:B34) -> 0 | C35: =SUM(C4:C34) -> 0 | D35: =SUM(D4:D34) -> 0 | E35: =SUM(E4:E34) -> 0 | F35: =F34 -> 0 | G35: =SUM(G4:G34) -> 0 | H35: =H34 -> 0 | I35: =SUM(I4:I34) -> 0 | J35: =J34 -> 0 | K35: =SUM(K4:K34) -> 0 | L35: =SUM(L4:L34) -> 0 | M35: =SUM(M4:M34) -> 0 | N35: =SUM(N4:N34) -> 0 | O35: =SUM(O4:O34) -> 0 | P35: =SUM(P4:P34) -> 0 | Q35: =SUM(Q4:Q34) -> 0 | R35: =SUM(R4:R34) -> 0 | ... W35: =SUM(W4:W34) -> 0

Sheet Osthoff-2
A3: Date | B3: Total prod. | C3: Process Demand | D3: Re-process | E3: Effective Production | F3: Mtd. prod. | G3: Prod. kg | H3: Mtd. prod. kg. | I3: Running Hours | J3: Mtd. Running Hours | K3: Mechnical | L3: Electrical | M3: Machine Cleaning | N3: Change Over | O3: P.M. | P3: No. power | Q3: No.Steam | R3: No. programe | S3: Man Power Shortage | T3: Mise(Other Opration Faults) | U3: Insect problem | V3: No. Trolley | W3: Total
E4: =+B4-D4-C4 -> 0 | H4: =G4 -> 0 | W4: =SUM(K4:V4) -> 0
E5: =+B5-D5-C5 -> 0 | H5: =G5+H4 -> 0 | W5: =SUM(K5:V5) -> 0
E6: =+B6-D6-C6 -> 0 | H6: =G6+H5 -> 0 | W6: =SUM(K6:V6) -> 0
E7: =+B7-D7-C7 -> 0 | H7: =G7+H6 -> 0 | W7: =SUM(K7:V7) -> 0
E8: =+B8-D8-C8 -> 0 | H8: =G8+H7 -> 0 | W8: =SUM(K8:V8) -> 0
E9: =+B9-D9-C9 -> 0 | H9: =G9+H8 -> 0 | W9: =SUM(K9:V9) -> 0
E10: =+B10-D10-C10 -> 0 | H10: =G10+H9 -> 0 | W10: =SUM(K10:V10) -> 0
E11: =+B11-D11-C11 -> 0 | H11: =G11+H10 -> 0 | W11: =SUM(K11:V11) -> 0
E12: =+B12-D12-C12 -> 0 | H12: =G12+H11 -> 0 | W12: =SUM(K12:V12) -> 0
E13: =+B13-D13-C13 -> 0 | H13: =G13+H12 -> 0 | W13: =SUM(K13:V13) -> 0
E14: =+B14-D14-C14 -> 0 | H14: =G14+H13 -> 0 | W14: =SUM(K14:V14) -> 0
E15: =+B15-D15-C15 -> 0 | H15: =G15+H14 -> 0 | W15: =SUM(K15:V15) -> 0
E16: =+B16-D16-C16 -> 0 | H16: =G16+H15 -> 0 | W16: =SUM(K16:V16) -> 0
... E34: =+B34-D34-C34 -> 0 | H34: =G34+H33 -> 0 | W34: =SUM(K34:V34) -> 0
A35: Total | B35: =SUM(B4:B34) -> 0 | C35: =SUM(C4:C34) -> 0 | D35: =SUM(D4:D34) -> 0 | E35: =SUM(E4:E34) -> 0 | F35: =F34 -> 0 | G35: =SUM(G4:G34) -> 0 | H35: =H34 -> 0 | I35: =SUM(I4:I34) -> 0 | J35: =J34 -> 0 | K35: =SUM(K4:K34) -> 0 | L35: =SUM(L4:L34) -> 0 | M35: =SUM(M4:M34) -> 0 | N35: =SUM(N4:N34) -> 0 | O35: =SUM(O4:O34) -> 0 | P35: =SUM(P4:P34) -> 0 | Q35: =SUM(Q4:Q34) -> 0 | R35: =SUM(R4:R34) -> 0 | ... W35: =SUM(W4:W34) -> 0

Sheet PTR
A3: Date | B3: Total prod. | C3: Process Demand | D3: Re-process | E3: Effective Production | F3: Mtd. prod. | G3: Prod. kg | H3: Mtd. prod. kg. | I3: Running Hours | J3: Mtd. Running Hours | K3: Mechnical | L3: Electrical | M3: Machine Cleaning | N3: Change Over | O3: P.M. | P3: No. power | Q3: No.Steam | R3: No. programe | S3: Man Power Shortage | T3: Mise(Other Opration Faults) | U3: Insect problem | V3: No. Trolley | W3: Total
E4: =+B4-D4-C4 -> 0 | H4: =G4 -> 0 | W4: =SUM(K4:V4) -> 0
E5: =+B5-D5-C5 -> 0 | H5: =G5+H4 -> 0 | W5: =SUM(K5:V5) -> 0
E6: =+B6-D6-C6 -> 0 | H6: =G6+H5 -> 0 | W6: =SUM(K6:V6) -> 0
E7: =+B7-D7-C7 -> 0 | H7: =G7+H6 -> 0 | W7: =SUM(K7:V7) -> 0
E8: =+B8-D8-C8 -> 0 | H8: =G8+H7 -> 0 | W8: =SUM(K8:V8) -> 0
E9: =+B9-D9-C9 -> 0 | H9: =G9+H8 -> 0 | W9: =SUM(K9:V9) -> 0
E10: =+B10-D10-C10 -> 0 | H10: =G10+H9 -> 0 | W10: =SUM(K10:V10) -> 0
E11: =+B11-D11-C11 -> 0 | H11: =G11+H10 -> 0 | W11: =SUM(K11:V11) -> 0
E12: =+B12-D12-C12 -> 0 | H12: =G12+H11 -> 0 | W12: =SUM(K12:V12) -> 0
E13: =+B13-D13-C13 -> 0 | H13: =G13+H12 -> 0 | W13: =SUM(K13:V13) -> 0
E14: =+B14-D14-C14 -> 0 | H14: =G14+H13 -> 0 | W14: =SUM(K14:V14) -> 0
E15: =+B15-D15-C15 -> 0 | H15: =G15+H14 -> 0 | W15: =SUM(K15:V15) -> 0
E16: =+B16-D16-C16 -> 0 | H16: =G16+H15 -> 0 | W16: =SUM(K16:V16) -> 0
... E34: =+B34-D34-C34 -> 0 | H34: =G34+H33 -> 0 | W34: =SUM(K34:V34) -> 0
A35: Total | B35: =SUM(B4:B34) -> 0 | C35: =SUM(C4:C34) -> 0 | D35: =SUM(D4:D34) -> 0 | E35: =SUM(E4:E34) -> 0 | F35: =F34 -> 0 | G35: =SUM(G4:G34) -> 0 | H35: =H34 -> 0 | I35: =SUM(I4:I34) -> 0 | J35: =J34 -> 0 | K35: =SUM(K4:K34) -> 0 | L35: =SUM(L4:L34) -> 0 | M35: =SUM(M4:M34) -> 0 | N35: =SUM(N4:N34) -> 0 | O35: =SUM(O4:O34) -> 0 | P35: =SUM(P4:P34) -> 0 | Q35: =SUM(Q4:Q34) -> 0 | R35: =SUM(R4:R34) -> 0 | ... W35: =SUM(W4:W34) -> 0

Sheet NPS
A3: Date | B3: Total prod. | C3: Process Demand | D3: Re-process | E3: Effective Production | F3: Mtd. prod. | G3: Prod. kg | H3: Mtd. prod. kg. | I3: Running Hours | J3: Mtd. Running Hours | K3: Mechnical | L3: Electrical | M3: Machine Cleaning | N3: Change Over | O3: P.M. | P3: No. power | Q3: No.Steam | R3: No. programe | S3: Man Power Shortage | T3: Mise(Other Opration Faults) | U3: Insect problem | V3: No. Trolley | W3: Total
E4: =+B4-D4-C4 -> 0 | H4: =G4 -> 0 | W4: =SUM(K4:V4) -> 0
E5: =+B5-D5-C5 -> 0 | H5: =G5+H4 -> 0 | W5: =SUM(K5:V5) -> 0
E6: =+B6-D6-C6 -> 0 | H6: =G6+H5 -> 0 | W6: =SUM(K6:V6) -> 0
E7: =+B7-D7-C7 -> 0 | H7: =G7+H6 -> 0 | W7: =SUM(K7:V7) -> 0
E8: =+B8-D8-C8 -> 0 | H8: =G8+H7 -> 0 | W8: =SUM(K8:V8) -> 0
E9: =+B9-D9-C9 -> 0 | H9: =G9+H8 -> 0 | W9: =SUM(K9:V9) -> 0
E10: =+B10-D10-C10 -> 0 | H10: =G10+H9 -> 0 | W10: =SUM(K10:V10) -> 0
E11: =+B11-D11-C11 -> 0 | H11: =G11+H10 -> 0 | W11: =SUM(K11:V11) -> 0
E12: =+B12-D12-C12 -> 0 | H12: =G12+H11 -> 0 | W12: =SUM(K12:V12) -> 0
E13: =+B13-D13-C13 -> 0 | H13: =G13+H12 -> 0 | W13: =SUM(K13:V13) -> 0
E14: =+B14-D14-C14 -> 0 | H14: =G14+H13 -> 0 | W14: =SUM(K14:V14) -> 0
E15: =+B15-D15-C15 -> 0 | H15: =G15+H14 -> 0 | W15: =SUM(K15:V15) -> 0
E16: =+B16-D16-C16 -> 0 | H16: =G16+H15 -> 0 | W16: =SUM(K16:V16) -> 0
... E34: =+B34-D34-C34 -> 0 | H34: =G34+H33 -> 0 | W34: =SUM(K34:V34) -> 0
A35: Total | B35: =SUM(B4:B34) -> 0 | C35: =SUM(C4:C34) -> 0 | D35: =SUM(D4:D34) -> 0 | E35: =SUM(E4:E34) -> 0 | F35: =F34 -> 0 | G35: =SUM(G4:G34) -> 0 | H35: =H34 -> 0 | I35: =SUM(I4:I34) -> 0 | J35: =J34 -> 0 | K35: =SUM(K4:K34) -> 0 | L35: =SUM(L4:L34) -> 0 | M35: =SUM(M4:M34) -> 0 | N35: =SUM(N4:N34) -> 0 | O35: =SUM(O4:O34) -> 0 | P35: =SUM(P4:P34) -> 0 | Q35: =SUM(Q4:Q34) -> 0 | R35: =SUM(R4:R34) -> 0 | ... W35: =SUM(W4:W34) -> 0

Sheet Perble
A3: Date | B3: Total prod. | C3: Process Demand | D3: Re-process | E3: Effective Production | F3: Mtd. prod. | G3: Prod. kg | H3: Mtd. prod. kg. | I3: Running Hours | J3: Mtd. Running Hours | K3: Mechnical | L3: Electrical | M3: Machine Cleaning | N3: Change Over | O3: P.M. | P3: No. power | Q3: No.Steam | R3: No. programe | S3: Man Power Shortage | T3: Mise(Other Opration Faults) | U3: Insect problem | V3: No. Trolley | W3: Total
E4: =+B4-D4-C4 -> 0 | H4: =G4 -> 0 | W4: =SUM(K4:V4) -> 0
E5: =+B5-D5-C5 -> 0 | H5: =G5+H4 -> 0 | W5: =SUM(K5:V5) -> 0
E6: =+B6-D6-C6 -> 0 | H6: =G6+H5 -> 0 | W6: =SUM(K6:V6) -> 0
E7: =+B7-D7-C7 -> 0 | H7: =G7+H6 -> 0 | W7: =SUM(K7:V7) -> 0
E8: =+B8-D8-C8 -> 0 | H8: =G8+H7 -> 0 | W8: =SUM(K8:V8) -> 0
E9: =+B9-D9-C9 -> 0 | H9: =G9+H8 -> 0 | W9: =SUM(K9:V9) -> 0
E10: =+B10-D10-C10 -> 0 | H10: =G10+H9 -> 0 | W10: =SUM(K10:V10) -> 0
E11: =+B11-D11-C11 -> 0 | H11: =G11+H10 -> 0 | W11: =SUM(K11:V11) -> 0
E12: =+B12-D12-C12 -> 0 | H12: =G12+H11 -> 0 | W12: =SUM(K12:V12) -> 0
E13: =+B13-D13-C13 -> 0 | H13: =G13+H12 -> 0 | W13: =SUM(K13:V13) -> 0
E14: =+B14-D14-C14 -> 0 | H14: =G14+H13 -> 0 | W14: =SUM(K14:V14) -> 0
E15: =+B15-D15-C15 -> 0 | H15: =G15+H14 -> 0 | W15: =SUM(K15:V15) -> 0
E16: =+B16-D16-C16 -> 0 | H16: =G16+H15 -> 0 | W16: =SUM(K16:V16) -> 0
... E34: =+B34-D34-C34 -> 0 | H34: =G34+H33 -> 0 | W34: =SUM(K34:V34) -> 0
A35: Total | B35: =SUM(B4:B34) -> 0 | C35: =SUM(C4:C34) -> 0 | D35: =SUM(D4:D34) -> 0 | E35: =SUM(E4:E34) -> 0 | F35: =F34 -> 0 | G35: =SUM(G4:G34) -> 0 | H35: =H34 -> 0 | I35: =SUM(I4:I34) -> 0 | J35: =J34 -> 0 | K35: =SUM(K4:K34) -> 0 | L35: =SUM(L4:L34) -> 0 | M35: =SUM(M4:M34) -> 0 | N35: =SUM(N4:N34) -> 0 | O35: =SUM(O4:O34) -> 0 | P35: =SUM(P4:P34) -> 0 | Q35: =SUM(Q4:Q34) -> 0 | R35: =SUM(R4:R34) -> 0 | ... W35: =SUM(W4:W34) -> 0

Sheet Lafer-1
A3: Date | B3: Total prod. | C3: Process Demand | D3: Re-process | E3: Effective Production | F3: Mtd. prod. | G3: Prod. kg | H3: Mtd. prod. kg. | I3: Running Hours | J3: Mtd. Running Hours | K3: Mechnical | L3: Electrical | M3: Machine Cleaning | N3: Change Over | O3: P.M. | P3: No. power | Q3: No.Steam | R3: No. programe | S3: Man Power Shortage | T3: Mise(Other Opration Faults) | U3: Insect problem | V3: No. Trolley | W3: Total
E4: =+B4-D4-C4 -> 0 | H4: =G4 -> 0 | W4: =SUM(K4:V4) -> 0
E5: =+B5-D5-C5 -> 0 | H5: =G5+H4 -> 0 | W5: =SUM(K5:V5) -> 0
E6: =+B6-D6-C6 -> 0 | H6: =G6+H5 -> 0 | W6: =SUM(K6:V6) -> 0
E7: =+B7-D7-C7 -> 0 | H7: =G7+H6 -> 0 | W7: =SUM(K7:V7) -> 0
E8: =+B8-D8-C8 -> 0 | H8: =G8+H7 -> 0 | W8: =SUM(K8:V8) -> 0
E9: =+B9-D9-C9 -> 0 | H9: =G9+H8 -> 0 | W9: =SUM(K9:V9) -> 0
E10: =+B10-D10-C10 -> 0 | H10: =G10+H9 -> 0 | W10: =SUM(K10:V10) -> 0
E11: =+B11-D11-C11 -> 0 | H11: =G11+H10 -> 0 | W11: =SUM(K11:V11) -> 0
E12: =+B12-D12-C12 -> 0 | H12: =G12+H11 -> 0 | W12: =SUM(K12:V12) -> 0
E13: =+B13-D13-C13 -> 0 | H13: =G13+H12 -> 0 | W13: =SUM(K13:V13) -> 0
E14: =+B14-D14-C14 -> 0 | H14: =G14+H13 -> 0 | W14: =SUM(K14:V14) -> 0
E15: =+B15-D15-C15 -> 0 | H15: =G15+H14 -> 0 | W15: =SUM(K15:V15) -> 0
E16: =+B16-D16-C16 -> 0 | H16: =G16+H15 -> 0 | W16: =SUM(K16:V16) -> 0
... E34: =+B34-D34-C34 -> 0 | H34: =G34+H33 -> 0 | W34: =SUM(K34:V34) -> 0
A35: Total | B35: =SUM(B4:B34) -> 0 | C35: =SUM(C4:C34) -> 0 | D35: =SUM(D4:D34) -> 0 | E35: =SUM(E4:E34) -> 0 | F35: =F34 -> 0 | G35: =SUM(G4:G34) -> 0 | H35: =H34 -> 0 | I35: =SUM(I4:I34) -> 0 | J35: =J34 -> 0 | K35: =SUM(K4:K34) -> 0 | L35: =SUM(L4:L34) -> 0 | M35: =SUM(M4:M34) -> 0 | N35: =SUM(N4:N34) -> 0 | O35: =SUM(O4:O34) -> 0 | P35: =SUM(P4:P34) -> 0 | Q35: =SUM(Q4:Q34) -> 0 | R35: =SUM(R4:R34) -> 0 | ... W35: =SUM(W4:W34) -> 0

Sheet Lafer-2
A3: Date | B3: Total prod. | C3: Process Demand | D3: Re-process | E3: Effective Production | F3: Mtd. prod. | G3: Prod. kg | H3: Mtd. prod. kg. | I3: Running Hours | J3: Mtd. Running Hours | K3: Mechnical | L3: Electrical | M3: Machine Cleaning | N3: Change Over | O3: P.M. | P3: No. power | Q3: No.Steam | R3: No. programe | S3: Man Power Shortage | T3: Mise(Other Opration Faults) | U3: Insect problem | V3: No. Trolley | W3: Total
E4: =+B4-D4-C4 -> 0 | H4: =G4 -> 0 | W4: =SUM(K4:V4) -> 0
E5: =+B5-D5-C5 -> 0 | H5: =G5+H4 -> 0 | W5: =SUM(K5:V5) -> 0
E6: =+B6-D6-C6 -> 0 | H6: =G6+H5 -> 0 | W6: =SUM(K6:V6) -> 0
E7: =+B7-D7-C7 -> 0 | H7: =G7+H6 -> 0 | W7: =SUM(K7:V7) -> 0
E8: =+B8-D8-C8 -> 0 | H8: =G8+H7 -> 0 | W8: =SUM(K8:V8) -> 0
E9: =+B9-D9-C9 -> 0 | H9: =G9+H8 -> 0 | W9: =SUM(K9:V9) -> 0
E10: =+B10-D10-C10 -> 0 | H10: =G10+H9 -> 0 | W10: =SUM(K10:V10) -> 0
E11: =+B11-D11-C11 -> 0 | H11: =G11+H10 -> 0 | W11: =SUM(K11:V11) -> 0
E12: =+B12-D12-C12 -> 0 | H12: =G12+H11 -> 0 | W12: =SUM(K12:V12) -> 0
E13: =+B13-D13-C13 -> 0 | H13: =G13+H12 -> 0 | W13: =SUM(K13:V13) -> 0
E14: =+B14-D14-C14 -> 0 | H14: =G14+H13 -> 0 | W14: =SUM(K14:V14) -> 0
E15: =+B15-D15-C15 -> 0 | H15: =G15+H14 -> 0 | W15: =SUM(K15:V15) -> 0
E16: =+B16-D16-C16 -> 0 | H16: =G16+H15 -> 0 | W16: =SUM(K16:V16) -> 0
... E34: =+B34-D34-C34 -> 0 | H34: =G34+H33 -> 0 | W34: =SUM(K34:V34) -> 0
A35: Total | B35: =SUM(B4:B34) -> 0 | C35: =SUM(C4:C34) -> 0 | D35: =SUM(D4:D34) -> 0 | E35: =SUM(E4:E34) -> 0 | F35: =F34 -> 0 | G35: =SUM(G4:G34) -> 0 | H35: =H34 -> 0 | I35: =SUM(I4:I34) -> 0 | J35: =J34 -> 0 | K35: =SUM(K4:K34) -> 0 | L35: =SUM(L4:L34) -> 0 | M35: =SUM(M4:M34) -> 0 | N35: =SUM(N4:N34) -> 0 | O35: =SUM(O4:O34) -> 0 | P35: =SUM(P4:P34) -> 0 | Q35: =SUM(Q4:Q34) -> 0 | R35: =SUM(R4:R34) -> 0 | ... W35: =SUM(W4:W34) -> 0

Sheet Lafer-3
A3: Date | B3: Total prod. | C3: Process Demand | D3: Re-process | E3: Effective Production | F3: Mtd. prod. | G3: Prod. kg | H3: Mtd. prod. kg. | I3: Running Hours | J3: Mtd. Running Hours | K3: Mechnical | L3: Electrical | M3: Machine Cleaning | N3: Change Over | O3: P.M. | P3: No. power | Q3: No.Steam | R3: No. programe | S3: Man Power Shortage | T3: Mise(Other Opration Faults) | U3: Insect problem | V3: No. Trolley | W3: Total
E4: =+B4-D4-C4 -> 0 | H4: =G4 -> 0 | W4: =SUM(K4:V4) -> 0
E5: =+B5-D5-C5 -> 0 | H5: =G5+H4 -> 0 | W5: =SUM(K5:V5) -> 0
E6: =+B6-D6-C6 -> 0 | H6: =G6+H5 -> 0 | W6: =SUM(K6:V6) -> 0
E7: =+B7-D7-C7 -> 0 | H7: =G7+H6 -> 0 | W7: =SUM(K7:V7) -> 0
E8: =+B8-D8-C8 -> 0 | H8: =G8+H7 -> 0 | W8: =SUM(K8:V8) -> 0
E9: =+B9-D9-C9 -> 0 | H9: =G9+H8 -> 0 | W9: =SUM(K9:V9) -> 0
E10: =+B10-D10-C10 -> 0 | H10: =G10+H9 -> 0 | W10: =SUM(K10:V10) -> 0
E11: =+B11-D11-C11 -> 0 | H11: =G11+H10 -> 0 | W11: =SUM(K11:V11) -> 0
E12: =+B12-D12-C12 -> 0 | H12: =G12+H11 -> 0 | W12: =SUM(K12:V12) -> 0
E13: =+B13-D13-C13 -> 0 | H13: =G13+H12 -> 0 | W13: =SUM(K13:V13) -> 0
E14: =+B14-D14-C14 -> 0 | H14: =G14+H13 -> 0 | W14: =SUM(K14:V14) -> 0
E15: =+B15-D15-C15 -> 0 | H15: =G15+H14 -> 0 | W15: =SUM(K15:V15) -> 0
E16: =+B16-D16-C16 -> 0 | H16: =G16+H15 -> 0 | W16: =SUM(K16:V16) -> 0
... E34: =+B34-D34-C34 -> 0 | H34: =G34+H33 -> 0 | W34: =SUM(K34:V34) -> 0
A35: Total | B35: =SUM(B4:B34) -> 0 | C35: =SUM(C4:C34) -> 0 | D35: =SUM(D4:D34) -> 0 | E35: =SUM(E4:E34) -> 0 | F35: =F34 -> 0 | G35: =SUM(G4:G34) -> 0 | H35: =H34 -> 0 | I35: =SUM(I4:I34) -> 0 | J35: =J34 -> 0 | K35: =SUM(K4:K34) -> 0 | L35: =SUM(L4:L34) -> 0 | M35: =SUM(M4:M34) -> 0 | N35: =SUM(N4:N34) -> 0 | O35: =SUM(O4:O34) -> 0 | P35: =SUM(P4:P34) -> 0 | Q35: =SUM(Q4:Q34) -> 0 | R35: =SUM(R4:R34) -> 0 | ... W35: =SUM(W4:W34) -> 0

Sheet Lafer-4
A3: Date | B3: Total prod. | C3: Process Demand | D3: Re-process | E3: Effective Production | F3: Mtd. prod. | G3: Prod. kg | H3: Mtd. prod. kg. | I3: Running Hours | J3: Mtd. Running Hours | K3: Mechnical | L3: Electrical | M3: Machine Cleaning | N3: Change Over | O3: P.M. | P3: No. power | Q3: No.Steam | R3: No. programe | S3: Man Power Shortage | T3: Mise(Other Opration Faults) | U3: Insect problem | V3: No. Trolley | W3: Total
E4: =+B4-D4-C4 -> 0 | H4: =G4 -> 0 | W4: =SUM(K4:V4) -> 0
E5: =+B5-D5-C5 -> 0 | H5: =G5+H4 -> 0 | W5: =SUM(K5:V5) -> 0
E6: =+B6-D6-C6 -> 0 | H6: =G6+H5 -> 0 | W6: =SUM(K6:V6) -> 0
E7: =+B7-D7-C7 -> 0 | H7: =G7+H6 -> 0 | W7: =SUM(K7:V7) -> 0
E8: =+B8-D8-C8 -> 0 | H8: =G8+H7 -> 0 | W8: =SUM(K8:V8) -> 0
E9: =+B9-D9-C9 -> 0 | H9: =G9+H8 -> 0 | W9: =SUM(K9:V9) -> 0
E10: =+B10-D10-C10 -> 0 | H10: =G10+H9 -> 0 | W10: =SUM(K10:V10) -> 0
E11: =+B11-D11-C11 -> 0 | H11: =G11+H10 -> 0 | W11: =SUM(K11:V11) -> 0
E12: =+B12-D12-C12 -> 0 | H12: =G12+H11 -> 0 | W12: =SUM(K12:V12) -> 0
E13: =+B13-D13-C13 -> 0 | H13: =G13+H12 -> 0 | W13: =SUM(K13:V13) -> 0
E14: =+B14-D14-C14 -> 0 | H14: =G14+H13 -> 0 | W14: =SUM(K14:V14) -> 0
E15: =+B15-D15-C15 -> 0 | H15: =G15+H14 -> 0 | W15: =SUM(K15:V15) -> 0
E16: =+B16-D16-C16 -> 0 | H16: =G16+H15 -> 0 | W16: =SUM(K16:V16) -> 0
... E34: =+B34-D34-C34 -> 0 | H34: =G34+H33 -> 0 | W34: =SUM(K34:V34) -> 0
A35: Total | B35: =SUM(B4:B34) -> 0 | C35: =SUM(C4:C34) -> 0 | D35: =SUM(D4:D34) -> 0 | E35: =SUM(E4:E34) -> 0 | F35: =F34 -> 0 | G35: =SUM(G4:G34) -> 0 | H35: =H34 -> 0 | I35: =SUM(I4:I34) -> 0 | J35: =J34 -> 0 | K35: =SUM(K4:K34) -> 0 | L35: =SUM(L4:L34) -> 0 | M35: =SUM(M4:M34) -> 0 | N35: =SUM(N4:N34) -> 0 | O35: =SUM(O4:O34) -> 0 | P35: =SUM(P4:P34) -> 0 | Q35: =SUM(Q4:Q34) -> 0 | R35: =SUM(R4:R34) -> 0 | ... W35: =SUM(W4:W34) -> 0

Sheet Lafer-5-Raising
A3: Date | B3: Total prod. | C3: Process Demand | D3: Re-process | E3: Effective Production | F3: Mtd. prod. | G3: Prod. kg | H3: Mtd. prod. kg. | I3: Running Hours | J3: Mtd. Running Hours | K3: Mechnical | L3: Electrical | M3: Machine Cleaning | N3: Change Over | O3: P.M. | P3: No. power | Q3: No.Steam | R3: No. programe | S3: Man Power Shortage | T3: Mise(Other Opration Faults) | U3: Insect problem | V3: No. Trolley | W3: Total
E4: =+B4-D4-C4 -> 0 | H4: =G4 -> 0 | W4: =SUM(K4:V4) -> 0
E5: =+B5-D5-C5 -> 0 | H5: =G5+H4 -> 0 | W5: =SUM(K5:V5) -> 0
E6: =+B6-D6-C6 -> 0 | H6: =G6+H5 -> 0 | W6: =SUM(K6:V6) -> 0
E7: =+B7-D7-C7 -> 0 | H7: =G7+H6 -> 0 | W7: =SUM(K7:V7) -> 0
E8: =+B8-D8-C8 -> 0 | H8: =G8+H7 -> 0 | W8: =SUM(K8:V8) -> 0
E9: =+B9-D9-C9 -> 0 | H9: =G9+H8 -> 0 | W9: =SUM(K9:V9) -> 0
E10: =+B10-D10-C10 -> 0 | H10: =G10+H9 -> 0 | W10: =SUM(K10:V10) -> 0
E11: =+B11-D11-C11 -> 0 | H11: =G11+H10 -> 0 | W11: =SUM(K11:V11) -> 0
E12: =+B12-D12-C12 -> 0 | H12: =G12+H11 -> 0 | W12: =SUM(K12:V12) -> 0
E13: =+B13-D13-C13 -> 0 | H13: =G13+H12 -> 0 | W13: =SUM(K13:V13) -> 0
E14: =+B14-D14-C14 -> 0 | H14: =G14+H13 -> 0 | W14: =SUM(K14:V14) -> 0
E15: =+B15-D15-C15 -> 0 | H15: =G15+H14 -> 0 | W15: =SUM(K15:V15) -> 0
E16: =+B16-D16-C16 -> 0 | H16: =G16+H15 -> 0 | W16: =SUM(K16:V16) -> 0
... E34: =+B34-D34-C34 -> 0 | H34: =G34+H33 -> 0 | W34: =SUM(K34:V34) -> 0
A35: Total | B35: =SUM(B4:B34) -> 0 | C35: =SUM(C4:C34) -> 0 | D35: =SUM(D4:D34) -> 0 | E35: =SUM(E4:E34) -> 0 | F35: =F34 -> 0 | G35: =SUM(G4:G34) -> 0 | H35: =H34 -> 0 | I35: =SUM(I4:I34) -> 0 | J35: =J34 -> 0 | K35: =SUM(K4:K34) -> 0 | L35: =SUM(L4:L34) -> 0 | M35: =SUM(M4:M34) -> 0 | N35: =SUM(N4:N34) -> 0 | O35: =SUM(O4:O34) -> 0 | P35: =SUM(P4:P34) -> 0 | Q35: =SUM(Q4:Q34) -> 0 | R35: =SUM(R4:R34) -> 0 | ... W35: =SUM(W4:W34) -> 0

Sheet Lafer-5-Shearing
A3: Date | B3: Total prod. | C3: Process Demand | D3: Re-process | E3: Effective Production | F3: Mtd. prod. | G3: Prod. kg | H3: Mtd. prod. kg. | I3: Running Hours | J3: Mtd. Running Hours | K3: Mechnical | L3: Electrical | M3: Machine Cleaning | N3: Change Over | O3: P.M. | P3: No. power | Q3: No.Steam | R3: No. programe | S3: Man Power Shortage | T3: Mise(Other Opration Faults) | U3: Insect problem | V3: No. Trolley | W3: Total
E4: =+B4-D4-C4 -> 0 | H4: =G4 -> 0 | W4: =SUM(K4:V4) -> 0
E5: =+B5-D5-C5 -> 0 | H5: =G5+H4 -> 0 | W5: =SUM(K5:V5) -> 0
E6: =+B6-D6-C6 -> 0 | H6: =G6+H5 -> 0 | W6: =SUM(K6:V6) -> 0
E7: =+B7-D7-C7 -> 0 | H7: =G7+H6 -> 0 | W7: =SUM(K7:V7) -> 0
E8: =+B8-D8-C8 -> 0 | H8: =G8+H7 -> 0 | W8: =SUM(K8:V8) -> 0
E9: =+B9-D9-C9 -> 0 | H9: =G9+H8 -> 0 | W9: =SUM(K9:V9) -> 0
E10: =+B10-D10-C10 -> 0 | H10: =G10+H9 -> 0 | W10: =SUM(K10:V10) -> 0
E11: =+B11-D11-C11 -> 0 | H11: =G11+H10 -> 0 | W11: =SUM(K11:V11) -> 0
E12: =+B12-D12-C12 -> 0 | H12: =G12+H11 -> 0 | W12: =SUM(K12:V12) -> 0
E13: =+B13-D13-C13 -> 0 | H13: =G13+H12 -> 0 | W13: =SUM(K13:V13) -> 0
E14: =+B14-D14-C14 -> 0 | H14: =G14+H13 -> 0 | W14: =SUM(K14:V14) -> 0
E15: =+B15-D15-C15 -> 0 | H15: =G15+H14 -> 0 | W15: =SUM(K15:V15) -> 0
E16: =+B16-D16-C16 -> 0 | H16: =G16+H15 -> 0 | W16: =SUM(K16:V16) -> 0
... E34: =+B34-D34-C34 -> 0 | H34: =G34+H33 -> 0 | W34: =SUM(K34:V34) -> 0
A35: Total | B35: =SUM(B4:B34) -> 0 | C35: =SUM(C4:C34) -> 0 | D35: =SUM(D4:D34) -> 0 | E35: =SUM(E4:E34) -> 0 | F35: =F34 -> 0 | G35: =SUM(G4:G34) -> 0 | H35: =H34 -> 0 | I35: =SUM(I4:I34) -> 0 | J35: =J34 -> 0 | K35: =SUM(K4:K34) -> 0 | L35: =SUM(L4:L34) -> 0 | M35: =SUM(M4:M34) -> 0 | N35: =SUM(N4:N34) -> 0 | O35: =SUM(O4:O34) -> 0 | P35: =SUM(P4:P34) -> 0 | Q35: =SUM(Q4:Q34) -> 0 | R35: =SUM(R4:R34) -> 0 | ... W35: =SUM(W4:W34) -> 0

Sheet Soaper
A3: Date | B3: Total prod. | C3: Process Demand | D3: Re-process | E3: Effective Production | F3: Mtd. prod. | G3: Prod. kg | H3: Mtd. prod. kg. | I3: Running Hours | J3: Mtd. Running Hours | K3: Mechnical | L3: Electrical | M3: Machine Cleaning | N3: Change Over | O3: P.M. | P3: No. power | Q3: No.Steam | R3: No. programe | S3: Man Power Shortage | T3: Mise(Other Opration Faults) | U3: Insect problem | V3: No. Trolley | W3: Total
E4: =+B4-D4-C4 -> 0 | H4: =G4 -> 0 | W4: =SUM(K4:V4) -> 0
E5: =+B5-D5-C5 -> 0 | H5: =G5+H4 -> 0 | W5: =SUM(K5:V5) -> 0
E6: =+B6-D6-C6 -> 0 | H6: =G6+H5 -> 0 | W6: =SUM(K6:V6) -> 0
E7: =+B7-D7-C7 -> 0 | H7: =G7+H6 -> 0 | W7: =SUM(K7:V7) -> 0
E8: =+B8-D8-C8 -> 0 | H8: =G8+H7 -> 0 | W8: =SUM(K8:V8) -> 0
E9: =+B9-D9-C9 -> 0 | H9: =G9+H8 -> 0 | W9: =SUM(K9:V9) -> 0
E10: =+B10-D10-C10 -> 0 | H10: =G10+H9 -> 0 | W10: =SUM(K10:V10) -> 0
E11: =+B11-D11-C11 -> 0 | H11: =G11+H10 -> 0 | W11: =SUM(K11:V11) -> 0
E12: =+B12-D12-C12 -> 0 | H12: =G12+H11 -> 0 | W12: =SUM(K12:V12) -> 0
E13: =+B13-D13-C13 -> 0 | H13: =G13+H12 -> 0 | W13: =SUM(K13:V13) -> 0
E14: =+B14-D14-C14 -> 0 | H14: =G14+H13 -> 0 | W14: =SUM(K14:V14) -> 0
E15: =+B15-D15-C15 -> 0 | H15: =G15+H14 -> 0 | W15: =SUM(K15:V15) -> 0
E16: =+B16-D16-C16 -> 0 | H16: =G16+H15 -> 0 | W16: =SUM(K16:V16) -> 0
... E34: =+B34-D34-C34 -> 0 | H34: =G34+H33 -> 0 | W34: =SUM(K34:V34) -> 0
A35: Total | B35: =SUM(B4:B34) -> 0 | C35: =SUM(C4:C34) -> 0 | D35: =SUM(D4:D34) -> 0 | E35: =SUM(E4:E34) -> 0 | F35: =F34 -> 0 | G35: =SUM(G4:G34) -> 0 | H35: =H34 -> 0 | I35: =SUM(I4:I34) -> 0 | J35: =J34 -> 0 | K35: =SUM(K4:K34) -> 0 | L35: =SUM(L4:L34) -> 0 | M35: =SUM(M4:M34) -> 0 | N35: =SUM(N4:N34) -> 0 | O35: =SUM(O4:O34) -> 0 | P35: =SUM(P4:P34) -> 0 | Q35: =SUM(Q4:Q34) -> 0 | R35: =SUM(R4:R34) -> 0 | ... W35: =SUM(W4:W34) -> 0

Sheet Merceriser-1
A3: Date | B3: Total prod. | C3: Process Demand | D3: Re-process | E3: Effective Production | F3: Mtd. prod. | G3: Prod. kg | H3: Mtd. prod. kg. | I3: Running Hours | J3: Mtd. Running Hours | K3: Mechnical | L3: Electrical | M3: Machine Cleaning | N3: Change Over | O3: P.M. | P3: No. power | Q3: No.Steam | R3: No. programe | S3: Man Power Shortage | T3: Mise(Other Opration Faults) | U3: Insect problem | V3: No. Trolley | W3: Total
E4: =+B4-D4-C4 -> 0 | H4: =G4 -> 0 | W4: =SUM(K4:V4) -> 0
E5: =+B5-D5-C5 -> 0 | H5: =G5+H4 -> 0 | W5: =SUM(K5:V5) -> 0
E6: =+B6-D6-C6 -> 0 | H6: =G6+H5 -> 0 | W6: =SUM(K6:V6) -> 0
E7: =+B7-D7-C7 -> 0 | H7: =G7+H6 -> 0 | W7: =SUM(K7:V7) -> 0
E8: =+B8-D8-C8 -> 0 | H8: =G8+H7 -> 0 | W8: =SUM(K8:V8) -> 0
E9: =+B9-D9-C9 -> 0 | H9: =G9+H8 -> 0 | W9: =SUM(K9:V9) -> 0
E10: =+B10-D10-C10 -> 0 | H10: =G10+H9 -> 0 | W10: =SUM(K10:V10) -> 0
E11: =+B11-D11-C11 -> 0 | H11: =G11+H10 -> 0 | W11: =SUM(K11:V11) -> 0
E12: =+B12-D12-C12 -> 0 | H12: =G12+H11 -> 0 | W12: =SUM(K12:V12) -> 0
E13: =+B13-D13-C13 -> 0 | H13: =G13+H12 -> 0 | W13: =SUM(K13:V13) -> 0
E14: =+B14-D14-C14 -> 0 | H14: =G14+H13 -> 0 | W14: =SUM(K14:V14) -> 0
E15: =+B15-D15-C15 -> 0 | H15: =G15+H14 -> 0 | W15: =SUM(K15:V15) -> 0
E16: =+B16-D16-C16 -> 0 | H16: =G16+H15 -> 0 | W16: =SUM(K16:V16) -> 0
... E34: =+B34-D34-C34 -> 0 | H34: =G34+H33 -> 0 | W34: =SUM(K34:V34) -> 0
A35: Total | B35: =SUM(B4:B34) -> 0 | C35: =SUM(C4:C34) -> 0 | D35: =SUM(D4:D34) -> 0 | E35: =SUM(E4:E34) -> 0 | F35: =F34 -> 0 | G35: =SUM(G4:G34) -> 0 | H35: =H34 -> 0 | I35: =SUM(I4:I34) -> 0 | J35: =J34 -> 0 | K35: =SUM(K4:K34) -> 0 | L35: =SUM(L4:L34) -> 0 | M35: =SUM(M4:M34) -> 0 | N35: =SUM(N4:N34) -> 0 | O35: =SUM(O4:O34) -> 0 | P35: =SUM(P4:P34) -> 0 | Q35: =SUM(Q4:Q34) -> 0 | R35: =SUM(R4:R34) -> 0 | ... W35: =SUM(W4:W34) -> 0

Sheet Merceriser-2
